package com.github.dayzminecraft.dayzminecraft.common.world.generation.structures;

import java.util.Random;

import net.minecraft.block.Block;
import net.minecraft.init.Blocks;
import net.minecraft.item.ItemDoor;
import net.minecraft.tileentity.TileEntity;
import net.minecraft.tileentity.TileEntityChest;
import net.minecraft.util.WeightedRandomChestContent;
import net.minecraft.world.World;

import com.github.dayzminecraft.dayzminecraft.common.blocks.ModBlocks;
import com.github.dayzminecraft.dayzminecraft.common.misc.ChatHandler;
import com.github.dayzminecraft.dayzminecraft.common.misc.LootManager;

public class StructureHouse implements IStructure {
  @Override
  public boolean generate(World world, Random rand, int xCoord, int yCoord, int zCoord) {
    Block baseBlock = Blocks.grass;
    Block airBlock = Blocks.air;

    if (world.getBlock(xCoord, yCoord, zCoord) != baseBlock ||
      world.getBlock(xCoord, yCoord + 1, zCoord) != airBlock ||
      world.getBlock(xCoord + 7, yCoord, zCoord) != baseBlock ||
      world.getBlock(xCoord + 7, yCoord, zCoord + 7) != baseBlock ||
      world.getBlock(xCoord, yCoord, zCoord + 7) != baseBlock ||
      world.getBlock(xCoord + 7, yCoord + 1, zCoord) != airBlock ||
      world.getBlock(xCoord + 7, yCoord + 1, zCoord + 7) != airBlock ||
      world.getBlock(xCoord, yCoord + 1, zCoord + 7) != airBlock) {
      return false;
    }

    world.setBlock(xCoord + 1, yCoord, zCoord + 9, Blocks.cobblestone);
    world.setBlock(xCoord + 1, yCoord, zCoord + 8, Blocks.cobblestone);
    world.setBlock(xCoord + 1, yCoord, zCoord + 7, Blocks.cobblestone);
    world.setBlock(xCoord + 1, yCoord, zCoord + 6, Blocks.cobblestone);
    world.setBlock(xCoord + 1, yCoord, zCoord + 5, Blocks.cobblestone);
    world.setBlock(xCoord + 1, yCoord, zCoord + 4, Blocks.cobblestone);
    world.setBlock(xCoord + 1, yCoord, zCoord + 3, Blocks.cobblestone);
    world.setBlock(xCoord + 1, yCoord, zCoord + 2, Blocks.cobblestone);
    world.setBlock(xCoord + 1, yCoord, zCoord + 1, Blocks.cobblestone);
    world.setBlock(xCoord + 2, yCoord, zCoord + 9, Blocks.cobblestone);
    world.setBlock(xCoord + 2, yCoord, zCoord + 8, Blocks.planks);
    world.setBlock(xCoord + 2, yCoord, zCoord + 7, Blocks.planks);
    world.setBlock(xCoord + 2, yCoord, zCoord + 6, Blocks.planks);
    world.setBlock(xCoord + 2, yCoord, zCoord + 5, Blocks.planks);
    world.setBlock(xCoord + 2, yCoord, zCoord + 4, Blocks.planks);
    world.setBlock(xCoord + 2, yCoord, zCoord + 3, Blocks.planks);
    world.setBlock(xCoord + 2, yCoord, zCoord + 2, Blocks.planks);
    world.setBlock(xCoord + 2, yCoord, zCoord + 1, Blocks.cobblestone);
    world.setBlock(xCoord + 3, yCoord, zCoord + 9, Blocks.cobblestone);
    world.setBlock(xCoord + 3, yCoord, zCoord + 8, Blocks.planks);
    world.setBlock(xCoord + 3, yCoord, zCoord + 7, Blocks.planks);
    world.setBlock(xCoord + 3, yCoord, zCoord + 6, Blocks.planks);
    world.setBlock(xCoord + 3, yCoord, zCoord + 5, Blocks.planks);
    world.setBlock(xCoord + 3, yCoord, zCoord + 4, Blocks.planks);
    world.setBlock(xCoord + 3, yCoord, zCoord + 3, Blocks.planks);
    world.setBlock(xCoord + 3, yCoord, zCoord + 2, Blocks.planks);
    world.setBlock(xCoord + 3, yCoord, zCoord + 1, Blocks.cobblestone);
    world.setBlock(xCoord + 4, yCoord, zCoord + 9, Blocks.cobblestone);
    world.setBlock(xCoord + 4, yCoord, zCoord + 8, Blocks.planks);
    world.setBlock(xCoord + 4, yCoord, zCoord + 7, Blocks.planks);
    world.setBlock(xCoord + 4, yCoord, zCoord + 6, Blocks.planks);
    world.setBlock(xCoord + 4, yCoord, zCoord + 5, Blocks.planks);
    world.setBlock(xCoord + 4, yCoord, zCoord + 4, Blocks.planks);
    world.setBlock(xCoord + 4, yCoord, zCoord + 3, Blocks.planks);
    world.setBlock(xCoord + 4, yCoord, zCoord + 2, Blocks.planks);
    world.setBlock(xCoord + 4, yCoord, zCoord + 1, Blocks.cobblestone);
    world.setBlock(xCoord + 5, yCoord, zCoord + 9, Blocks.cobblestone);
    world.setBlock(xCoord + 5, yCoord, zCoord + 8, Blocks.planks);
    world.setBlock(xCoord + 5, yCoord, zCoord + 7, Blocks.planks);
    world.setBlock(xCoord + 5, yCoord, zCoord + 6, Blocks.planks);
    world.setBlock(xCoord + 5, yCoord, zCoord + 5, Blocks.planks);
    world.setBlock(xCoord + 5, yCoord, zCoord + 4, Blocks.planks);
    world.setBlock(xCoord + 5, yCoord, zCoord + 3, Blocks.planks);
    world.setBlock(xCoord + 5, yCoord, zCoord + 2, Blocks.planks);
    world.setBlock(xCoord + 5, yCoord, zCoord + 1, Blocks.cobblestone);
    world.setBlock(xCoord + 6, yCoord, zCoord + 9, Blocks.cobblestone);
    world.setBlock(xCoord + 6, yCoord, zCoord + 8, Blocks.planks);
    world.setBlock(xCoord + 6, yCoord, zCoord + 7, Blocks.planks);
    world.setBlock(xCoord + 6, yCoord, zCoord + 6, Blocks.planks);
    world.setBlock(xCoord + 6, yCoord, zCoord + 5, Blocks.planks);
    world.setBlock(xCoord + 6, yCoord, zCoord + 4, Blocks.planks);
    world.setBlock(xCoord + 6, yCoord, zCoord + 3, Blocks.planks);
    world.setBlock(xCoord + 6, yCoord, zCoord + 2, Blocks.planks);
    world.setBlock(xCoord + 6, yCoord, zCoord + 1, Blocks.cobblestone);
    world.setBlock(xCoord + 7, yCoord, zCoord + 9, Blocks.cobblestone);
    world.setBlock(xCoord + 7, yCoord, zCoord + 8, Blocks.planks);
    world.setBlock(xCoord + 7, yCoord, zCoord + 7, Blocks.planks);
    world.setBlock(xCoord + 7, yCoord, zCoord + 6, Blocks.planks);
    world.setBlock(xCoord + 7, yCoord, zCoord + 5, Blocks.planks);
    world.setBlock(xCoord + 7, yCoord, zCoord + 4, Blocks.planks);
    world.setBlock(xCoord + 7, yCoord, zCoord + 3, Blocks.planks);
    world.setBlock(xCoord + 7, yCoord, zCoord + 2, Blocks.planks);
    world.setBlock(xCoord + 7, yCoord, zCoord + 1, Blocks.cobblestone);
    world.setBlock(xCoord + 8, yCoord, zCoord + 9, Blocks.cobblestone);
    world.setBlock(xCoord + 8, yCoord, zCoord + 8, Blocks.planks);
    world.setBlock(xCoord + 8, yCoord, zCoord + 7, Blocks.planks);
    world.setBlock(xCoord + 8, yCoord, zCoord + 6, Blocks.planks);
    world.setBlock(xCoord + 8, yCoord, zCoord + 5, Blocks.planks);
    world.setBlock(xCoord + 8, yCoord, zCoord + 4, Blocks.planks);
    world.setBlock(xCoord + 8, yCoord, zCoord + 3, Blocks.planks);
    world.setBlock(xCoord + 8, yCoord, zCoord + 2, Blocks.planks);
    world.setBlock(xCoord + 8, yCoord, zCoord + 1, Blocks.cobblestone);
    world.setBlock(xCoord + 9, yCoord, zCoord + 9, Blocks.cobblestone);
    world.setBlock(xCoord + 9, yCoord, zCoord + 8, Blocks.cobblestone);
    world.setBlock(xCoord + 9, yCoord, zCoord + 7, Blocks.cobblestone);
    world.setBlock(xCoord + 9, yCoord, zCoord + 6, Blocks.cobblestone);
    world.setBlock(xCoord + 9, yCoord, zCoord + 5, Blocks.cobblestone);
    world.setBlock(xCoord + 9, yCoord, zCoord + 4, Blocks.cobblestone);
    world.setBlock(xCoord + 9, yCoord, zCoord + 3, Blocks.cobblestone);
    world.setBlock(xCoord + 9, yCoord, zCoord + 2, Blocks.cobblestone);
    world.setBlock(xCoord + 9, yCoord, zCoord + 1, Blocks.cobblestone);
    world.setBlock(xCoord + 1, yCoord + 1, zCoord + 9, Blocks.log);
    world.setBlock(xCoord + 1, yCoord + 1, zCoord + 8, Blocks.planks);
    world.setBlock(xCoord + 1, yCoord + 1, zCoord + 7, Blocks.planks);
    world.setBlock(xCoord + 1, yCoord + 1, zCoord + 6, Blocks.planks);
    ItemDoor.placeDoorBlock(world, xCoord + 1, yCoord + 1, zCoord + 5, 0, Blocks.wooden_door);
    world.setBlock(xCoord + 1, yCoord + 1, zCoord + 4, Blocks.planks);
    world.setBlock(xCoord + 1, yCoord + 1, zCoord + 3, Blocks.planks);
    world.setBlock(xCoord + 1, yCoord + 1, zCoord + 2, Blocks.planks);
    world.setBlock(xCoord + 1, yCoord + 1, zCoord + 1, Blocks.log);
    world.setBlock(xCoord + 2, yCoord + 1, zCoord + 9, Blocks.planks);
    world.setBlockToAir(xCoord + 2, yCoord + 1, zCoord + 8);
    world.setBlockToAir(xCoord + 2, yCoord + 1, zCoord + 7);
    world.setBlockToAir(xCoord + 2, yCoord + 1, zCoord + 6);
    world.setBlockToAir(xCoord + 2, yCoord + 1, zCoord + 5);
    world.setBlockToAir(xCoord + 2, yCoord + 1, zCoord + 4);
    world.setBlockToAir(xCoord + 2, yCoord + 1, zCoord + 3);
    world.setBlock(xCoord + 2, yCoord + 1, zCoord + 2, Blocks.bookshelf);
    world.setBlock(xCoord + 2, yCoord + 1, zCoord + 1, Blocks.planks);
    world.setBlock(xCoord + 3, yCoord + 1, zCoord + 9, Blocks.planks);
    world.setBlockToAir(xCoord + 3, yCoord + 1, zCoord + 8);
    world.setBlock(xCoord + 3, yCoord + 1, zCoord + 7, Blocks.fence);
    world.setBlockToAir(xCoord + 3, yCoord + 1, zCoord + 6);
    world.setBlockToAir(xCoord + 3, yCoord + 1, zCoord + 5);
    world.setBlockToAir(xCoord + 3, yCoord + 1, zCoord + 4);
    world.setBlockToAir(xCoord + 3, yCoord + 1, zCoord + 3);
    world.setBlock(xCoord + 3, yCoord + 1, zCoord + 2, Blocks.bookshelf);
    world.setBlock(xCoord + 3, yCoord + 1, zCoord + 1, Blocks.planks);
    world.setBlock(xCoord + 4, yCoord + 1, zCoord + 9, Blocks.planks);
    world.setBlockToAir(xCoord + 4, yCoord + 1, zCoord + 8);
    world.setBlockToAir(xCoord + 4, yCoord + 1, zCoord + 7);
    world.setBlockToAir(xCoord + 4, yCoord + 1, zCoord + 6);
    world.setBlockToAir(xCoord + 4, yCoord + 1, zCoord + 5);
    world.setBlockToAir(xCoord + 4, yCoord + 1, zCoord + 4);
    world.setBlockToAir(xCoord + 4, yCoord + 1, zCoord + 3);
    world.setBlock(xCoord + 4, yCoord + 1, zCoord + 2, Blocks.bookshelf);
    world.setBlock(xCoord + 4, yCoord + 1, zCoord + 1, Blocks.planks);
    world.setBlock(xCoord + 5, yCoord + 1, zCoord + 9, Blocks.planks);
    world.setBlockToAir(xCoord + 5, yCoord + 1, zCoord + 8);
    world.setBlockToAir(xCoord + 5, yCoord + 1, zCoord + 7);
    world.setBlockToAir(xCoord + 5, yCoord + 1, zCoord + 6);
    world.setBlockToAir(xCoord + 5, yCoord + 1, zCoord + 5);
    world.setBlockToAir(xCoord + 5, yCoord + 1, zCoord + 4);
    world.setBlockToAir(xCoord + 5, yCoord + 1, zCoord + 3);
    world.setBlock(xCoord + 5, yCoord + 1, zCoord + 2, Blocks.bookshelf);
    world.setBlock(xCoord + 5, yCoord + 1, zCoord + 1, Blocks.planks);
    world.setBlock(xCoord + 6, yCoord + 1, zCoord + 9, Blocks.planks);
    world.setBlockToAir(xCoord + 6, yCoord + 1, zCoord + 8);
    world.setBlock(xCoord + 6, yCoord + 1, zCoord + 7, Blocks.fence);
    world.setBlockToAir(xCoord + 6, yCoord + 1, zCoord + 6);
    world.setBlockToAir(xCoord + 6, yCoord + 1, zCoord + 5);
    world.setBlockToAir(xCoord + 6, yCoord + 1, zCoord + 4);
    world.setBlockToAir(xCoord + 6, yCoord + 1, zCoord + 3);
    world.setBlock(xCoord + 6, yCoord + 1, zCoord + 2, Blocks.bookshelf);
    world.setBlock(xCoord + 6, yCoord + 1, zCoord + 1, Blocks.planks);
    world.setBlock(xCoord + 7, yCoord + 1, zCoord + 9, Blocks.planks);
    world.setBlockToAir(xCoord + 7, yCoord + 1, zCoord + 8);
    world.setBlockToAir(xCoord + 7, yCoord + 1, zCoord + 7);
    world.setBlockToAir(xCoord + 7, yCoord + 1, zCoord + 6);
    world.setBlockToAir(xCoord + 7, yCoord + 1, zCoord + 5);
    world.setBlockToAir(xCoord + 7, yCoord + 1, zCoord + 4);
    world.setBlockToAir(xCoord + 7, yCoord + 1, zCoord + 3);
    world.setBlock(xCoord + 7, yCoord + 1, zCoord + 2, Blocks.bookshelf);
    world.setBlock(xCoord + 7, yCoord + 1, zCoord + 1, Blocks.planks);
    world.setBlock(xCoord + 8, yCoord + 1, zCoord + 9, Blocks.planks);
    world.setBlock(xCoord + 8, yCoord + 1, zCoord + 8, Blocks.bookshelf);
    world.setBlock(xCoord + 8, yCoord + 1, zCoord + 7, Blocks.furnace);
    world.setBlock(xCoord + 8, yCoord + 1, zCoord + 6, Blocks.furnace);

    Block chest = ModBlocks.chestLoot;
    world.setBlock(xCoord + 8, yCoord + 1, zCoord + 5, chest);
    TileEntity tileentitychest = world.getTileEntity(xCoord + 8, yCoord + 1, zCoord + 5);
    if (tileentitychest != null) {
      WeightedRandomChestContent.generateChestContents(rand, LootManager.loot, (TileEntityChest)tileentitychest, rand.nextInt(5) + 1);
    }
    ChatHandler.logDebug("Day Z House Chest Created At " + (xCoord + 8) + ", " + (yCoord + 1) + ", " + (zCoord + 5) + ".");

    world.setBlock(xCoord + 8, yCoord + 1, zCoord + 4, Blocks.crafting_table);
    world.setBlockToAir(xCoord + 8, yCoord + 1, zCoord + 3);
    world.setBlock(xCoord + 8, yCoord + 1, zCoord + 2, Blocks.bookshelf);
    world.setBlock(xCoord + 8, yCoord + 1, zCoord + 1, Blocks.planks);
    world.setBlock(xCoord + 9, yCoord + 1, zCoord + 9, Blocks.log);
    world.setBlock(xCoord + 9, yCoord + 1, zCoord + 8, Blocks.planks);
    world.setBlock(xCoord + 9, yCoord + 1, zCoord + 7, Blocks.planks);
    world.setBlock(xCoord + 9, yCoord + 1, zCoord + 6, Blocks.planks);
    world.setBlock(xCoord + 9, yCoord + 1, zCoord + 5, Blocks.planks);
    world.setBlock(xCoord + 9, yCoord + 1, zCoord + 4, Blocks.planks);
    world.setBlock(xCoord + 9, yCoord + 1, zCoord + 3, Blocks.planks);
    world.setBlock(xCoord + 9, yCoord + 1, zCoord + 2, Blocks.planks);
    world.setBlock(xCoord + 9, yCoord + 1, zCoord + 1, Blocks.log);
    world.setBlock(xCoord + 1, yCoord + 2, zCoord + 9, Blocks.log);
    world.setBlock(xCoord + 1, yCoord + 2, zCoord + 8, Blocks.glass_pane);
    world.setBlock(xCoord + 1, yCoord + 2, zCoord + 7, Blocks.glass_pane);
    world.setBlock(xCoord + 1, yCoord + 2, zCoord + 6, Blocks.planks);
    world.setBlock(xCoord + 1, yCoord + 2, zCoord + 4, Blocks.planks);
    world.setBlock(xCoord + 1, yCoord + 2, zCoord + 3, Blocks.glass_pane);
    world.setBlock(xCoord + 1, yCoord + 2, zCoord + 2, Blocks.glass_pane);
    world.setBlock(xCoord + 1, yCoord + 2, zCoord + 1, Blocks.log);
    world.setBlock(xCoord + 2, yCoord + 2, zCoord + 9, Blocks.planks);
    world.setBlockToAir(xCoord + 2, yCoord + 2, zCoord + 8);
    world.setBlockToAir(xCoord + 2, yCoord + 2, zCoord + 7);
    world.setBlockToAir(xCoord + 2, yCoord + 2, zCoord + 6);
    world.setBlockToAir(xCoord + 2, yCoord + 2, zCoord + 5);
    world.setBlockToAir(xCoord + 2, yCoord + 2, zCoord + 4);
    world.setBlockToAir(xCoord + 2, yCoord + 2, zCoord + 3);
    world.setBlock(xCoord + 2, yCoord + 2, zCoord + 2, Blocks.bookshelf);
    world.setBlock(xCoord + 2, yCoord + 2, zCoord + 1, Blocks.planks);
    world.setBlock(xCoord + 3, yCoord + 2, zCoord + 9, Blocks.glass_pane);
    world.setBlockToAir(xCoord + 3, yCoord + 2, zCoord + 8);
    world.setBlock(xCoord + 3, yCoord + 2, zCoord + 7, Blocks.wooden_pressure_plate);
    world.setBlockToAir(xCoord + 3, yCoord + 2, zCoord + 6);
    world.setBlockToAir(xCoord + 3, yCoord + 2, zCoord + 5);
    world.setBlockToAir(xCoord + 3, yCoord + 2, zCoord + 4);
    world.setBlockToAir(xCoord + 3, yCoord + 2, zCoord + 3);
    world.setBlockToAir(xCoord + 3, yCoord + 2, zCoord + 2);
    world.setBlock(xCoord + 3, yCoord + 2, zCoord + 1, Blocks.glass_pane);
    world.setBlock(xCoord + 4, yCoord + 2, zCoord + 9, Blocks.glass_pane);
    world.setBlockToAir(xCoord + 4, yCoord + 2, zCoord + 8);
    world.setBlockToAir(xCoord + 4, yCoord + 2, zCoord + 7);
    world.setBlockToAir(xCoord + 4, yCoord + 2, zCoord + 6);
    world.setBlockToAir(xCoord + 4, yCoord + 2, zCoord + 5);
    world.setBlockToAir(xCoord + 4, yCoord + 2, zCoord + 4);
    world.setBlockToAir(xCoord + 4, yCoord + 2, zCoord + 3);
    world.setBlockToAir(xCoord + 4, yCoord + 2, zCoord + 2);
    world.setBlock(xCoord + 4, yCoord + 2, zCoord + 1, Blocks.glass_pane);
    world.setBlock(xCoord + 5, yCoord + 2, zCoord + 10, Blocks.torch);
    world.setBlock(xCoord + 5, yCoord + 2, zCoord + 9, Blocks.planks);
    world.setBlock(xCoord + 5, yCoord + 2, zCoord + 8, Blocks.torch);
    world.setBlockToAir(xCoord + 5, yCoord + 2, zCoord + 7);
    world.setBlockToAir(xCoord + 5, yCoord + 2, zCoord + 6);
    world.setBlockToAir(xCoord + 5, yCoord + 2, zCoord + 5);
    world.setBlockToAir(xCoord + 5, yCoord + 2, zCoord + 4);
    world.setBlockToAir(xCoord + 5, yCoord + 2, zCoord + 3);
    world.setBlock(xCoord + 5, yCoord + 2, zCoord + 2, Blocks.torch);
    world.setBlock(xCoord + 5, yCoord + 2, zCoord + 1, Blocks.planks);
    world.setBlock(xCoord + 5, yCoord + 2, zCoord, Blocks.torch);
    world.setBlock(xCoord + 6, yCoord + 2, zCoord + 9, Blocks.glass_pane);
    world.setBlockToAir(xCoord + 6, yCoord + 2, zCoord + 8);
    world.setBlock(xCoord + 6, yCoord + 2, zCoord + 7, Blocks.wooden_pressure_plate);
    world.setBlockToAir(xCoord + 6, yCoord + 2, zCoord + 6);
    world.setBlockToAir(xCoord + 6, yCoord + 2, zCoord + 5);
    world.setBlockToAir(xCoord + 6, yCoord + 2, zCoord + 4);
    world.setBlockToAir(xCoord + 6, yCoord + 2, zCoord + 3);
    world.setBlockToAir(xCoord + 6, yCoord + 2, zCoord + 2);
    world.setBlock(xCoord + 6, yCoord + 2, zCoord + 1, Blocks.glass_pane);
    world.setBlock(xCoord + 7, yCoord + 2, zCoord + 9, Blocks.glass_pane);
    world.setBlockToAir(xCoord + 7, yCoord + 2, zCoord + 8);
    world.setBlockToAir(xCoord + 7, yCoord + 2, zCoord + 7);
    world.setBlockToAir(xCoord + 7, yCoord + 2, zCoord + 6);
    world.setBlockToAir(xCoord + 7, yCoord + 2, zCoord + 5);
    world.setBlockToAir(xCoord + 7, yCoord + 2, zCoord + 4);
    world.setBlockToAir(xCoord + 7, yCoord + 2, zCoord + 3);
    world.setBlockToAir(xCoord + 7, yCoord + 2, zCoord + 2);
    world.setBlock(xCoord + 7, yCoord + 2, zCoord + 1, Blocks.glass_pane);
    world.setBlock(xCoord + 8, yCoord + 2, zCoord + 9, Blocks.planks);
    world.setBlock(xCoord + 8, yCoord + 2, zCoord + 8, Blocks.bookshelf);
    world.setBlockToAir(xCoord + 8, yCoord + 2, zCoord + 7);
    world.setBlockToAir(xCoord + 8, yCoord + 2, zCoord + 6);
    world.setBlockToAir(xCoord + 8, yCoord + 2, zCoord + 5);
    world.setBlockToAir(xCoord + 8, yCoord + 2, zCoord + 4);
    world.setBlockToAir(xCoord + 8, yCoord + 2, zCoord + 3);
    world.setBlock(xCoord + 8, yCoord + 2, zCoord + 2, Blocks.bookshelf);
    world.setBlock(xCoord + 8, yCoord + 2, zCoord + 1, Blocks.planks);
    world.setBlock(xCoord + 9, yCoord + 2, zCoord + 9, Blocks.log);
    world.setBlock(xCoord + 9, yCoord + 2, zCoord + 8, Blocks.planks);
    world.setBlock(xCoord + 9, yCoord + 2, zCoord + 7, Blocks.glass_pane);
    world.setBlock(xCoord + 9, yCoord + 2, zCoord + 6, Blocks.glass_pane);
    world.setBlock(xCoord + 9, yCoord + 2, zCoord + 5, Blocks.planks);
    world.setBlock(xCoord + 9, yCoord + 2, zCoord + 4, Blocks.glass_pane);
    world.setBlock(xCoord + 9, yCoord + 2, zCoord + 3, Blocks.glass_pane);
    world.setBlock(xCoord + 9, yCoord + 2, zCoord + 2, Blocks.planks);
    world.setBlock(xCoord + 9, yCoord + 2, zCoord + 1, Blocks.log);
    world.setBlock(xCoord + 10, yCoord + 2, zCoord + 5, Blocks.torch);
    world.setBlock(xCoord, yCoord + 3, zCoord + 5, Blocks.torch);
    world.setBlock(xCoord + 1, yCoord + 3, zCoord + 10, Blocks.cobblestone);
    world.setBlock(xCoord + 1, yCoord + 3, zCoord + 9, Blocks.log);
    world.setBlock(xCoord + 1, yCoord + 3, zCoord + 8, Blocks.planks);
    world.setBlock(xCoord + 1, yCoord + 3, zCoord + 7, Blocks.planks);
    world.setBlock(xCoord + 1, yCoord + 3, zCoord + 6, Blocks.planks);
    world.setBlock(xCoord + 1, yCoord + 3, zCoord + 5, Blocks.planks);
    world.setBlock(xCoord + 1, yCoord + 3, zCoord + 4, Blocks.planks);
    world.setBlock(xCoord + 1, yCoord + 3, zCoord + 3, Blocks.planks);
    world.setBlock(xCoord + 1, yCoord + 3, zCoord + 2, Blocks.planks);
    world.setBlock(xCoord + 1, yCoord + 3, zCoord + 1, Blocks.log);
    world.setBlock(xCoord + 1, yCoord + 3, zCoord, Blocks.cobblestone);
    world.setBlock(xCoord + 2, yCoord + 3, zCoord + 10, Blocks.cobblestone);
    world.setBlock(xCoord + 2, yCoord + 3, zCoord + 9, Blocks.planks);
    world.setBlockToAir(xCoord + 2, yCoord + 3, zCoord + 8);
    world.setBlock(xCoord + 2, yCoord + 3, zCoord + 7, Blocks.torch);
    world.setBlockToAir(xCoord + 2, yCoord + 3, zCoord + 6);
    world.setBlockToAir(xCoord + 2, yCoord + 3, zCoord + 5);
    world.setBlock(xCoord + 2, yCoord + 3, zCoord + 4, Blocks.torch);
    world.setBlockToAir(xCoord + 2, yCoord + 3, zCoord + 3);
    world.setBlock(xCoord + 2, yCoord + 3, zCoord + 2, Blocks.bookshelf);
    world.setBlock(xCoord + 2, yCoord + 3, zCoord + 1, Blocks.planks);
    world.setBlock(xCoord + 2, yCoord + 3, zCoord, Blocks.cobblestone);
    world.setBlock(xCoord + 3, yCoord + 3, zCoord + 10, Blocks.cobblestone);
    world.setBlock(xCoord + 3, yCoord + 3, zCoord + 9, Blocks.planks);
    world.setBlockToAir(xCoord + 3, yCoord + 3, zCoord + 8);
    world.setBlockToAir(xCoord + 3, yCoord + 3, zCoord + 7);
    world.setBlockToAir(xCoord + 3, yCoord + 3, zCoord + 6);
    world.setBlockToAir(xCoord + 3, yCoord + 3, zCoord + 5);
    world.setBlockToAir(xCoord + 3, yCoord + 3, zCoord + 4);
    world.setBlockToAir(xCoord + 3, yCoord + 3, zCoord + 3);
    world.setBlockToAir(xCoord + 3, yCoord + 3, zCoord + 2);
    world.setBlock(xCoord + 3, yCoord + 3, zCoord + 1, Blocks.planks);
    world.setBlock(xCoord + 3, yCoord + 3, zCoord, Blocks.cobblestone);
    world.setBlock(xCoord + 4, yCoord + 3, zCoord + 10, Blocks.cobblestone);
    world.setBlock(xCoord + 4, yCoord + 3, zCoord + 9, Blocks.planks);
    world.setBlockToAir(xCoord + 4, yCoord + 3, zCoord + 8);
    world.setBlockToAir(xCoord + 4, yCoord + 3, zCoord + 7);
    world.setBlockToAir(xCoord + 4, yCoord + 3, zCoord + 6);
    world.setBlockToAir(xCoord + 4, yCoord + 3, zCoord + 5);
    world.setBlockToAir(xCoord + 4, yCoord + 3, zCoord + 4);
    world.setBlockToAir(xCoord + 4, yCoord + 3, zCoord + 3);
    world.setBlockToAir(xCoord + 4, yCoord + 3, zCoord + 2);
    world.setBlock(xCoord + 4, yCoord + 3, zCoord + 1, Blocks.planks);
    world.setBlock(xCoord + 4, yCoord + 3, zCoord, Blocks.cobblestone);
    world.setBlock(xCoord + 5, yCoord + 3, zCoord + 10, Blocks.cobblestone);
    world.setBlock(xCoord + 5, yCoord + 3, zCoord + 9, Blocks.planks);
    world.setBlockToAir(xCoord + 5, yCoord + 3, zCoord + 8);
    world.setBlockToAir(xCoord + 5, yCoord + 3, zCoord + 7);
    world.setBlockToAir(xCoord + 5, yCoord + 3, zCoord + 6);
    world.setBlockToAir(xCoord + 5, yCoord + 3, zCoord + 5);
    world.setBlockToAir(xCoord + 5, yCoord + 3, zCoord + 4);
    world.setBlockToAir(xCoord + 5, yCoord + 3, zCoord + 3);
    world.setBlockToAir(xCoord + 5, yCoord + 3, zCoord + 2);
    world.setBlock(xCoord + 5, yCoord + 3, zCoord + 1, Blocks.planks);
    world.setBlock(xCoord + 5, yCoord + 3, zCoord, Blocks.cobblestone);
    world.setBlock(xCoord + 6, yCoord + 3, zCoord + 10, Blocks.cobblestone);
    world.setBlock(xCoord + 6, yCoord + 3, zCoord + 9, Blocks.planks);
    world.setBlockToAir(xCoord + 6, yCoord + 3, zCoord + 8);
    world.setBlockToAir(xCoord + 6, yCoord + 3, zCoord + 7);
    world.setBlockToAir(xCoord + 6, yCoord + 3, zCoord + 6);
    world.setBlockToAir(xCoord + 6, yCoord + 3, zCoord + 5);
    world.setBlockToAir(xCoord + 6, yCoord + 3, zCoord + 4);
    world.setBlockToAir(xCoord + 6, yCoord + 3, zCoord + 3);
    world.setBlockToAir(xCoord + 6, yCoord + 3, zCoord + 2);
    world.setBlock(xCoord + 6, yCoord + 3, zCoord + 1, Blocks.planks);
    world.setBlock(xCoord + 6, yCoord + 3, zCoord, Blocks.cobblestone);
    world.setBlock(xCoord + 7, yCoord + 3, zCoord + 10, Blocks.cobblestone);
    world.setBlock(xCoord + 7, yCoord + 3, zCoord + 9, Blocks.planks);
    world.setBlockToAir(xCoord + 7, yCoord + 3, zCoord + 8);
    world.setBlockToAir(xCoord + 7, yCoord + 3, zCoord + 7);
    world.setBlockToAir(xCoord + 7, yCoord + 3, zCoord + 6);
    world.setBlockToAir(xCoord + 7, yCoord + 3, zCoord + 5);
    world.setBlockToAir(xCoord + 7, yCoord + 3, zCoord + 4);
    world.setBlockToAir(xCoord + 7, yCoord + 3, zCoord + 3);
    world.setBlockToAir(xCoord + 7, yCoord + 3, zCoord + 2);
    world.setBlock(xCoord + 7, yCoord + 3, zCoord + 1, Blocks.planks);
    world.setBlock(xCoord + 7, yCoord + 3, zCoord, Blocks.cobblestone);
    world.setBlock(xCoord + 8, yCoord + 3, zCoord + 10, Blocks.cobblestone);
    world.setBlock(xCoord + 8, yCoord + 3, zCoord + 9, Blocks.planks);
    world.setBlockToAir(xCoord + 8, yCoord + 3, zCoord + 8);
    world.setBlock(xCoord + 8, yCoord + 3, zCoord + 7, Blocks.torch);
    world.setBlockToAir(xCoord + 8, yCoord + 3, zCoord + 6);
    world.setBlockToAir(xCoord + 8, yCoord + 3, zCoord + 5);
    world.setBlock(xCoord + 8, yCoord + 3, zCoord + 4, Blocks.torch);
    world.setBlockToAir(xCoord + 8, yCoord + 3, zCoord + 3);
    world.setBlock(xCoord + 8, yCoord + 3, zCoord + 2, Blocks.bookshelf);
    world.setBlock(xCoord + 8, yCoord + 3, zCoord + 1, Blocks.planks);
    world.setBlock(xCoord + 8, yCoord + 3, zCoord, Blocks.cobblestone);
    world.setBlock(xCoord + 9, yCoord + 3, zCoord + 10, Blocks.cobblestone);
    world.setBlock(xCoord + 9, yCoord + 3, zCoord + 9, Blocks.log);
    world.setBlock(xCoord + 9, yCoord + 3, zCoord + 8, Blocks.planks);
    world.setBlock(xCoord + 9, yCoord + 3, zCoord + 7, Blocks.planks);
    world.setBlock(xCoord + 9, yCoord + 3, zCoord + 6, Blocks.planks);
    world.setBlock(xCoord + 9, yCoord + 3, zCoord + 5, Blocks.planks);
    world.setBlock(xCoord + 9, yCoord + 3, zCoord + 4, Blocks.planks);
    world.setBlock(xCoord + 9, yCoord + 3, zCoord + 3, Blocks.planks);
    world.setBlock(xCoord + 9, yCoord + 3, zCoord + 2, Blocks.planks);
    world.setBlock(xCoord + 9, yCoord + 3, zCoord + 1, Blocks.log);
    world.setBlock(xCoord + 9, yCoord + 3, zCoord, Blocks.cobblestone);
    world.setBlock(xCoord + 1, yCoord + 4, zCoord + 9, Blocks.cobblestone);
    world.setBlock(xCoord + 1, yCoord + 4, zCoord + 8, Blocks.log);
    world.setBlock(xCoord + 1, yCoord + 4, zCoord + 7, Blocks.planks);
    world.setBlock(xCoord + 1, yCoord + 4, zCoord + 6, Blocks.glass_pane);
    world.setBlock(xCoord + 1, yCoord + 4, zCoord + 5, Blocks.glass_pane);
    world.setBlock(xCoord + 1, yCoord + 4, zCoord + 4, Blocks.glass_pane);
    world.setBlock(xCoord + 1, yCoord + 4, zCoord + 3, Blocks.planks);
    world.setBlock(xCoord + 1, yCoord + 4, zCoord + 2, Blocks.log);
    world.setBlock(xCoord + 1, yCoord + 4, zCoord + 1, Blocks.cobblestone);
    world.setBlock(xCoord + 2, yCoord + 4, zCoord + 9, Blocks.cobblestone);
    world.setBlockToAir(xCoord + 2, yCoord + 4, zCoord + 8);
    world.setBlockToAir(xCoord + 2, yCoord + 4, zCoord + 7);
    world.setBlockToAir(xCoord + 2, yCoord + 4, zCoord + 6);
    world.setBlockToAir(xCoord + 2, yCoord + 4, zCoord + 5);
    world.setBlockToAir(xCoord + 2, yCoord + 4, zCoord + 4);
    world.setBlockToAir(xCoord + 2, yCoord + 4, zCoord + 3);
    world.setBlockToAir(xCoord + 2, yCoord + 4, zCoord + 2);
    world.setBlock(xCoord + 2, yCoord + 4, zCoord + 1, Blocks.cobblestone);
    world.setBlock(xCoord + 3, yCoord + 4, zCoord + 9, Blocks.cobblestone);
    world.setBlockToAir(xCoord + 3, yCoord + 4, zCoord + 8);
    world.setBlockToAir(xCoord + 3, yCoord + 4, zCoord + 7);
    world.setBlockToAir(xCoord + 3, yCoord + 4, zCoord + 6);
    world.setBlockToAir(xCoord + 3, yCoord + 4, zCoord + 5);
    world.setBlockToAir(xCoord + 3, yCoord + 4, zCoord + 4);
    world.setBlockToAir(xCoord + 3, yCoord + 4, zCoord + 3);
    world.setBlockToAir(xCoord + 3, yCoord + 4, zCoord + 2);
    world.setBlock(xCoord + 3, yCoord + 4, zCoord + 1, Blocks.cobblestone);
    world.setBlock(xCoord + 4, yCoord + 4, zCoord + 9, Blocks.cobblestone);
    world.setBlockToAir(xCoord + 4, yCoord + 4, zCoord + 8);
    world.setBlockToAir(xCoord + 4, yCoord + 4, zCoord + 7);
    world.setBlockToAir(xCoord + 4, yCoord + 4, zCoord + 6);
    world.setBlockToAir(xCoord + 4, yCoord + 4, zCoord + 5);
    world.setBlockToAir(xCoord + 4, yCoord + 4, zCoord + 4);
    world.setBlockToAir(xCoord + 4, yCoord + 4, zCoord + 3);
    world.setBlockToAir(xCoord + 4, yCoord + 4, zCoord + 2);
    world.setBlock(xCoord + 4, yCoord + 4, zCoord + 1, Blocks.cobblestone);
    world.setBlock(xCoord + 5, yCoord + 4, zCoord + 9, Blocks.cobblestone);
    world.setBlockToAir(xCoord + 5, yCoord + 4, zCoord + 8);
    world.setBlockToAir(xCoord + 5, yCoord + 4, zCoord + 7);
    world.setBlockToAir(xCoord + 5, yCoord + 4, zCoord + 6);
    world.setBlockToAir(xCoord + 5, yCoord + 4, zCoord + 5);
    world.setBlockToAir(xCoord + 5, yCoord + 4, zCoord + 4);
    world.setBlockToAir(xCoord + 5, yCoord + 4, zCoord + 3);
    world.setBlockToAir(xCoord + 5, yCoord + 4, zCoord + 2);
    world.setBlock(xCoord + 5, yCoord + 4, zCoord + 1, Blocks.cobblestone);
    world.setBlock(xCoord + 6, yCoord + 4, zCoord + 9, Blocks.cobblestone);
    world.setBlockToAir(xCoord + 6, yCoord + 4, zCoord + 8);
    world.setBlockToAir(xCoord + 6, yCoord + 4, zCoord + 7);
    world.setBlockToAir(xCoord + 6, yCoord + 4, zCoord + 6);
    world.setBlockToAir(xCoord + 6, yCoord + 4, zCoord + 5);
    world.setBlockToAir(xCoord + 6, yCoord + 4, zCoord + 4);
    world.setBlockToAir(xCoord + 6, yCoord + 4, zCoord + 3);
    world.setBlockToAir(xCoord + 6, yCoord + 4, zCoord + 2);
    world.setBlock(xCoord + 6, yCoord + 4, zCoord + 1, Blocks.cobblestone);
    world.setBlock(xCoord + 7, yCoord + 4, zCoord + 9, Blocks.cobblestone);
    world.setBlockToAir(xCoord + 7, yCoord + 4, zCoord + 8);
    world.setBlockToAir(xCoord + 7, yCoord + 4, zCoord + 7);
    world.setBlockToAir(xCoord + 7, yCoord + 4, zCoord + 6);
    world.setBlockToAir(xCoord + 7, yCoord + 4, zCoord + 5);
    world.setBlockToAir(xCoord + 7, yCoord + 4, zCoord + 4);
    world.setBlockToAir(xCoord + 7, yCoord + 4, zCoord + 3);
    world.setBlockToAir(xCoord + 7, yCoord + 4, zCoord + 2);
    world.setBlock(xCoord + 7, yCoord + 4, zCoord + 1, Blocks.cobblestone);
    world.setBlock(xCoord + 8, yCoord + 4, zCoord + 9, Blocks.cobblestone);
    world.setBlockToAir(xCoord + 8, yCoord + 4, zCoord + 8);
    world.setBlockToAir(xCoord + 8, yCoord + 4, zCoord + 7);
    world.setBlockToAir(xCoord + 8, yCoord + 4, zCoord + 6);
    world.setBlockToAir(xCoord + 8, yCoord + 4, zCoord + 5);
    world.setBlockToAir(xCoord + 8, yCoord + 4, zCoord + 4);
    world.setBlockToAir(xCoord + 8, yCoord + 4, zCoord + 3);
    world.setBlockToAir(xCoord + 8, yCoord + 4, zCoord + 2);
    world.setBlock(xCoord + 8, yCoord + 4, zCoord + 1, Blocks.cobblestone);
    world.setBlock(xCoord + 9, yCoord + 4, zCoord + 9, Blocks.cobblestone);
    world.setBlock(xCoord + 9, yCoord + 4, zCoord + 8, Blocks.log);
    world.setBlock(xCoord + 9, yCoord + 4, zCoord + 7, Blocks.planks);
    world.setBlock(xCoord + 9, yCoord + 4, zCoord + 6, Blocks.glass_pane);
    world.setBlock(xCoord + 9, yCoord + 4, zCoord + 5, Blocks.glass_pane);
    world.setBlock(xCoord + 9, yCoord + 4, zCoord + 4, Blocks.glass_pane);
    world.setBlock(xCoord + 9, yCoord + 4, zCoord + 3, Blocks.planks);
    world.setBlock(xCoord + 9, yCoord + 4, zCoord + 2, Blocks.log);
    world.setBlock(xCoord + 9, yCoord + 4, zCoord + 1, Blocks.cobblestone);
    world.setBlock(xCoord + 1, yCoord + 5, zCoord + 8, Blocks.cobblestone);
    world.setBlock(xCoord + 1, yCoord + 5, zCoord + 7, Blocks.log);
    world.setBlock(xCoord + 1, yCoord + 5, zCoord + 6, Blocks.planks);
    world.setBlock(xCoord + 1, yCoord + 5, zCoord + 5, Blocks.glass_pane);
    world.setBlock(xCoord + 1, yCoord + 5, zCoord + 4, Blocks.planks);
    world.setBlock(xCoord + 1, yCoord + 5, zCoord + 3, Blocks.log);
    world.setBlock(xCoord + 1, yCoord + 5, zCoord + 2, Blocks.cobblestone);
    world.setBlock(xCoord + 2, yCoord + 5, zCoord + 8, Blocks.cobblestone);
    world.setBlockToAir(xCoord + 2, yCoord + 5, zCoord + 7);
    world.setBlockToAir(xCoord + 2, yCoord + 5, zCoord + 6);
    world.setBlockToAir(xCoord + 2, yCoord + 5, zCoord + 5);
    world.setBlockToAir(xCoord + 2, yCoord + 5, zCoord + 4);
    world.setBlockToAir(xCoord + 2, yCoord + 5, zCoord + 3);
    world.setBlock(xCoord + 2, yCoord + 5, zCoord + 2, Blocks.cobblestone);
    world.setBlock(xCoord + 3, yCoord + 5, zCoord + 8, Blocks.cobblestone);
    world.setBlockToAir(xCoord + 3, yCoord + 5, zCoord + 7);
    world.setBlockToAir(xCoord + 3, yCoord + 5, zCoord + 6);
    world.setBlockToAir(xCoord + 3, yCoord + 5, zCoord + 5);
    world.setBlockToAir(xCoord + 3, yCoord + 5, zCoord + 4);
    world.setBlockToAir(xCoord + 3, yCoord + 5, zCoord + 3);
    world.setBlock(xCoord + 3, yCoord + 5, zCoord + 2, Blocks.cobblestone);
    world.setBlock(xCoord + 4, yCoord + 5, zCoord + 8, Blocks.cobblestone);
    world.setBlockToAir(xCoord + 4, yCoord + 5, zCoord + 7);
    world.setBlockToAir(xCoord + 4, yCoord + 5, zCoord + 6);
    world.setBlockToAir(xCoord + 4, yCoord + 5, zCoord + 5);
    world.setBlockToAir(xCoord + 4, yCoord + 5, zCoord + 4);
    world.setBlockToAir(xCoord + 4, yCoord + 5, zCoord + 3);
    world.setBlock(xCoord + 4, yCoord + 5, zCoord + 2, Blocks.cobblestone);
    world.setBlock(xCoord + 5, yCoord + 5, zCoord + 8, Blocks.cobblestone);
    world.setBlockToAir(xCoord + 5, yCoord + 5, zCoord + 7);
    world.setBlockToAir(xCoord + 5, yCoord + 5, zCoord + 6);
    world.setBlockToAir(xCoord + 5, yCoord + 5, zCoord + 5);
    world.setBlockToAir(xCoord + 5, yCoord + 5, zCoord + 4);
    world.setBlockToAir(xCoord + 5, yCoord + 5, zCoord + 3);
    world.setBlock(xCoord + 5, yCoord + 5, zCoord + 2, Blocks.cobblestone);
    world.setBlock(xCoord + 6, yCoord + 5, zCoord + 8, Blocks.cobblestone);
    world.setBlockToAir(xCoord + 6, yCoord + 5, zCoord + 7);
    world.setBlockToAir(xCoord + 6, yCoord + 5, zCoord + 6);
    world.setBlockToAir(xCoord + 6, yCoord + 5, zCoord + 5);
    world.setBlockToAir(xCoord + 6, yCoord + 5, zCoord + 4);
    world.setBlockToAir(xCoord + 6, yCoord + 5, zCoord + 3);
    world.setBlock(xCoord + 6, yCoord + 5, zCoord + 2, Blocks.cobblestone);
    world.setBlock(xCoord + 7, yCoord + 5, zCoord + 8, Blocks.cobblestone);
    world.setBlockToAir(xCoord + 7, yCoord + 5, zCoord + 7);
    world.setBlockToAir(xCoord + 7, yCoord + 5, zCoord + 6);
    world.setBlockToAir(xCoord + 7, yCoord + 5, zCoord + 5);
    world.setBlockToAir(xCoord + 7, yCoord + 5, zCoord + 4);
    world.setBlockToAir(xCoord + 7, yCoord + 5, zCoord + 3);
    world.setBlock(xCoord + 7, yCoord + 5, zCoord + 2, Blocks.cobblestone);
    world.setBlock(xCoord + 8, yCoord + 5, zCoord + 8, Blocks.cobblestone);
    world.setBlockToAir(xCoord + 8, yCoord + 5, zCoord + 7);
    world.setBlockToAir(xCoord + 8, yCoord + 5, zCoord + 6);
    world.setBlockToAir(xCoord + 8, yCoord + 5, zCoord + 5);
    world.setBlockToAir(xCoord + 8, yCoord + 5, zCoord + 4);
    world.setBlockToAir(xCoord + 8, yCoord + 5, zCoord + 3);
    world.setBlock(xCoord + 8, yCoord + 5, zCoord + 2, Blocks.cobblestone);
    world.setBlock(xCoord + 9, yCoord + 5, zCoord + 8, Blocks.cobblestone);
    world.setBlock(xCoord + 9, yCoord + 5, zCoord + 7, Blocks.log);
    world.setBlock(xCoord + 9, yCoord + 5, zCoord + 6, Blocks.planks);
    world.setBlock(xCoord + 9, yCoord + 5, zCoord + 5, Blocks.glass_pane);
    world.setBlock(xCoord + 9, yCoord + 5, zCoord + 4, Blocks.planks);
    world.setBlock(xCoord + 9, yCoord + 5, zCoord + 3, Blocks.log);
    world.setBlock(xCoord + 9, yCoord + 5, zCoord + 2, Blocks.cobblestone);
    world.setBlock(xCoord + 1, yCoord + 6, zCoord + 7, Blocks.cobblestone);
    world.setBlock(xCoord + 1, yCoord + 6, zCoord + 6, Blocks.log);
    world.setBlock(xCoord + 1, yCoord + 6, zCoord + 5, Blocks.planks);
    world.setBlock(xCoord + 1, yCoord + 6, zCoord + 4, Blocks.log);
    world.setBlock(xCoord + 1, yCoord + 6, zCoord + 3, Blocks.cobblestone);
    world.setBlock(xCoord + 2, yCoord + 6, zCoord + 7, Blocks.cobblestone);
    world.setBlockToAir(xCoord + 2, yCoord + 6, zCoord + 6);
    world.setBlockToAir(xCoord + 2, yCoord + 6, zCoord + 5);
    world.setBlockToAir(xCoord + 2, yCoord + 6, zCoord + 4);
    world.setBlock(xCoord + 2, yCoord + 6, zCoord + 3, Blocks.cobblestone);
    world.setBlock(xCoord + 3, yCoord + 6, zCoord + 7, Blocks.cobblestone);
    world.setBlockToAir(xCoord + 3, yCoord + 6, zCoord + 6);
    world.setBlockToAir(xCoord + 3, yCoord + 6, zCoord + 5);
    world.setBlockToAir(xCoord + 3, yCoord + 6, zCoord + 4);
    world.setBlock(xCoord + 3, yCoord + 6, zCoord + 3, Blocks.cobblestone);
    world.setBlock(xCoord + 4, yCoord + 6, zCoord + 7, Blocks.cobblestone);
    world.setBlockToAir(xCoord + 4, yCoord + 6, zCoord + 6);
    world.setBlockToAir(xCoord + 4, yCoord + 6, zCoord + 5);
    world.setBlockToAir(xCoord + 4, yCoord + 6, zCoord + 4);
    world.setBlock(xCoord + 4, yCoord + 6, zCoord + 3, Blocks.cobblestone);
    world.setBlock(xCoord + 5, yCoord + 6, zCoord + 7, Blocks.cobblestone);
    world.setBlockToAir(xCoord + 5, yCoord + 6, zCoord + 6);
    world.setBlockToAir(xCoord + 5, yCoord + 6, zCoord + 5);
    world.setBlockToAir(xCoord + 5, yCoord + 6, zCoord + 4);
    world.setBlock(xCoord + 5, yCoord + 6, zCoord + 3, Blocks.cobblestone);
    world.setBlock(xCoord + 6, yCoord + 6, zCoord + 7, Blocks.cobblestone);
    world.setBlockToAir(xCoord + 6, yCoord + 6, zCoord + 6);
    world.setBlockToAir(xCoord + 6, yCoord + 6, zCoord + 5);
    world.setBlockToAir(xCoord + 6, yCoord + 6, zCoord + 4);
    world.setBlock(xCoord + 6, yCoord + 6, zCoord + 3, Blocks.cobblestone);
    world.setBlock(xCoord + 7, yCoord + 6, zCoord + 7, Blocks.cobblestone);
    world.setBlockToAir(xCoord + 7, yCoord + 6, zCoord + 6);
    world.setBlockToAir(xCoord + 7, yCoord + 6, zCoord + 5);
    world.setBlockToAir(xCoord + 7, yCoord + 6, zCoord + 4);
    world.setBlock(xCoord + 7, yCoord + 6, zCoord + 3, Blocks.cobblestone);
    world.setBlock(xCoord + 8, yCoord + 6, zCoord + 7, Blocks.cobblestone);
    world.setBlockToAir(xCoord + 8, yCoord + 6, zCoord + 6);
    world.setBlockToAir(xCoord + 8, yCoord + 6, zCoord + 5);
    world.setBlockToAir(xCoord + 8, yCoord + 6, zCoord + 4);
    world.setBlock(xCoord + 8, yCoord + 6, zCoord + 3, Blocks.cobblestone);
    world.setBlock(xCoord + 9, yCoord + 6, zCoord + 7, Blocks.cobblestone);
    world.setBlock(xCoord + 9, yCoord + 6, zCoord + 6, Blocks.log);
    world.setBlock(xCoord + 9, yCoord + 6, zCoord + 5, Blocks.planks);
    world.setBlock(xCoord + 9, yCoord + 6, zCoord + 4, Blocks.log);
    world.setBlock(xCoord + 9, yCoord + 6, zCoord + 3, Blocks.cobblestone);
    world.setBlock(xCoord + 1, yCoord + 7, zCoord + 6, Blocks.cobblestone);
    world.setBlock(xCoord + 1, yCoord + 7, zCoord + 5, Blocks.log);
    world.setBlock(xCoord + 1, yCoord + 7, zCoord + 4, Blocks.cobblestone);
    world.setBlock(xCoord + 2, yCoord + 7, zCoord + 6, Blocks.cobblestone);
    world.setBlockToAir(xCoord + 2, yCoord + 7, zCoord + 5);
    world.setBlock(xCoord + 2, yCoord + 7, zCoord + 4, Blocks.cobblestone);
    world.setBlock(xCoord + 3, yCoord + 7, zCoord + 6, Blocks.cobblestone);
    world.setBlockToAir(xCoord + 3, yCoord + 7, zCoord + 5);
    world.setBlock(xCoord + 3, yCoord + 7, zCoord + 4, Blocks.cobblestone);
    world.setBlock(xCoord + 4, yCoord + 7, zCoord + 6, Blocks.cobblestone);
    world.setBlockToAir(xCoord + 4, yCoord + 7, zCoord + 5);
    world.setBlock(xCoord + 4, yCoord + 7, zCoord + 4, Blocks.cobblestone);
    world.setBlock(xCoord + 5, yCoord + 7, zCoord + 6, Blocks.cobblestone);
    world.setBlockToAir(xCoord + 5, yCoord + 7, zCoord + 5);
    world.setBlock(xCoord + 5, yCoord + 7, zCoord + 4, Blocks.cobblestone);
    world.setBlock(xCoord + 6, yCoord + 7, zCoord + 6, Blocks.cobblestone);
    world.setBlockToAir(xCoord + 6, yCoord + 7, zCoord + 5);
    world.setBlock(xCoord + 6, yCoord + 7, zCoord + 4, Blocks.cobblestone);
    world.setBlock(xCoord + 7, yCoord + 7, zCoord + 6, Blocks.cobblestone);
    world.setBlockToAir(xCoord + 7, yCoord + 7, zCoord + 5);
    world.setBlock(xCoord + 7, yCoord + 7, zCoord + 4, Blocks.cobblestone);
    world.setBlock(xCoord + 8, yCoord + 7, zCoord + 6, Blocks.cobblestone);
    world.setBlockToAir(xCoord + 8, yCoord + 7, zCoord + 5);
    world.setBlock(xCoord + 8, yCoord + 7, zCoord + 4, Blocks.cobblestone);
    world.setBlock(xCoord + 9, yCoord + 7, zCoord + 6, Blocks.cobblestone);
    world.setBlock(xCoord + 9, yCoord + 7, zCoord + 5, Blocks.log);
    world.setBlock(xCoord + 9, yCoord + 7, zCoord + 4, Blocks.cobblestone);
    world.setBlock(xCoord + 1, yCoord + 8, zCoord + 5, Blocks.cobblestone);
    world.setBlock(xCoord + 2, yCoord + 8, zCoord + 5, Blocks.cobblestone);
    world.setBlock(xCoord + 3, yCoord + 8, zCoord + 5, Blocks.cobblestone);
    world.setBlock(xCoord + 4, yCoord + 8, zCoord + 5, Blocks.cobblestone);
    world.setBlock(xCoord + 5, yCoord + 8, zCoord + 5, Blocks.cobblestone);
    world.setBlock(xCoord + 6, yCoord + 8, zCoord + 5, Blocks.cobblestone);
    world.setBlock(xCoord + 7, yCoord + 8, zCoord + 5, Blocks.cobblestone);
    world.setBlock(xCoord + 8, yCoord + 8, zCoord + 5, Blocks.cobblestone);
    world.setBlock(xCoord + 9, yCoord + 8, zCoord + 5, Blocks.cobblestone);
    return true;
  }
}