package com.github.dayzminecraft.dayzminecraft.common.world.generation.structures;

import java.util.Random;

import net.minecraft.block.Block;
import net.minecraft.init.Blocks;
import net.minecraft.item.ItemDoor;
import net.minecraft.tileentity.TileEntity;
import net.minecraft.tileentity.TileEntityChest;
import net.minecraft.util.BlockPos;
import net.minecraft.util.WeightedRandomChestContent;
import net.minecraft.world.World;

import com.github.dayzminecraft.dayzminecraft.common.blocks.ModBlocks;
import com.github.dayzminecraft.dayzminecraft.common.misc.ChatHandler;
import com.github.dayzminecraft.dayzminecraft.common.misc.LootManager;

public class StructureFort implements IStructure {
  /*@Override
  public boolean generate(World world, Random rand, int xCoord, int yCoord, int zCoord) {
    Block baseBlock = Blocks.grass;
    Block airBlock = Blocks.air;

    if (world.getBlock(xCoord, yCoord, zCoord) != baseBlock ||
      world.getBlock(xCoord, yCoord + 1, zCoord) != airBlock ||
      world.getBlock(xCoord + 7, yCoord, zCoord) != baseBlock ||
      world.getBlock(xCoord + 7, yCoord, zCoord + 7) != baseBlock ||
      world.getBlock(xCoord, yCoord, zCoord + 7) != baseBlock ||
      world.getBlock(xCoord + 7, yCoord + 1, zCoord) != airBlock ||
      world.getBlock(xCoord + 7, yCoord + 1, zCoord + 7) != airBlock ||
      world.getBlock(xCoord, yCoord + 1, zCoord + 7) != airBlock) {
      return false;
    }

    world.setBlock(xCoord + 1, yCoord, zCoord + 5, Blocks.stonebrick, rand.nextInt(3), 2);
    world.setBlock(xCoord + 1, yCoord, zCoord + 4, Blocks.stonebrick, rand.nextInt(3), 2);
    world.setBlock(xCoord + 1, yCoord, zCoord + 3, Blocks.stonebrick, rand.nextInt(3), 2);
    world.setBlock(xCoord + 1, yCoord, zCoord + 2, Blocks.stonebrick, rand.nextInt(3), 2);
    world.setBlock(xCoord + 1, yCoord, zCoord + 1, Blocks.stonebrick, rand.nextInt(3), 2);
    world.setBlock(xCoord + 2, yCoord, zCoord + 5, Blocks.stonebrick, rand.nextInt(3), 2);
    world.setBlock(xCoord + 2, yCoord, zCoord + 4, Blocks.stonebrick, rand.nextInt(3), 2);
    world.setBlock(xCoord + 2, yCoord, zCoord + 3, Blocks.stonebrick, rand.nextInt(3), 2);
    world.setBlock(xCoord + 2, yCoord, zCoord + 2, Blocks.stonebrick, rand.nextInt(3), 2);
    world.setBlock(xCoord + 2, yCoord, zCoord + 1, Blocks.stonebrick, rand.nextInt(3), 2);
    world.setBlock(xCoord + 3, yCoord, zCoord + 5, Blocks.stonebrick, rand.nextInt(3), 2);
    world.setBlock(xCoord + 3, yCoord, zCoord + 4, Blocks.stonebrick, rand.nextInt(3), 2);
    world.setBlock(xCoord + 3, yCoord, zCoord + 3, Blocks.stonebrick, rand.nextInt(3), 2);
    world.setBlock(xCoord + 3, yCoord, zCoord + 2, Blocks.stonebrick, rand.nextInt(3), 2);
    world.setBlock(xCoord + 3, yCoord, zCoord + 1, Blocks.stonebrick, rand.nextInt(3), 2);
    world.setBlock(xCoord + 4, yCoord, zCoord + 5, Blocks.stonebrick, rand.nextInt(3), 2);
    world.setBlock(xCoord + 4, yCoord, zCoord + 4, Blocks.stonebrick, rand.nextInt(3), 2);
    world.setBlock(xCoord + 4, yCoord, zCoord + 3, Blocks.stonebrick, rand.nextInt(3), 2);
    world.setBlock(xCoord + 4, yCoord, zCoord + 2, Blocks.stonebrick, rand.nextInt(3), 2);
    world.setBlock(xCoord + 4, yCoord, zCoord + 1, Blocks.stonebrick, rand.nextInt(3), 2);
    world.setBlock(xCoord + 5, yCoord, zCoord + 5, Blocks.stonebrick, rand.nextInt(3), 2);
    world.setBlock(xCoord + 5, yCoord, zCoord + 4, Blocks.stonebrick, rand.nextInt(3), 2);
    world.setBlock(xCoord + 5, yCoord, zCoord + 3, Blocks.stonebrick, rand.nextInt(3), 2);
    world.setBlock(xCoord + 5, yCoord, zCoord + 2, Blocks.stonebrick, rand.nextInt(3), 2);
    world.setBlock(xCoord + 5, yCoord, zCoord + 1, Blocks.stonebrick, rand.nextInt(3), 2);
    world.setBlock(xCoord + 1, yCoord + 1, zCoord + 5, Blocks.stonebrick, rand.nextInt(3), 2);
    world.setBlock(xCoord + 1, yCoord + 1, zCoord + 4, Blocks.stonebrick, rand.nextInt(3), 2);
    world.setBlock(xCoord + 1, yCoord + 1, zCoord + 3, Blocks.stonebrick, rand.nextInt(3), 2);
    world.setBlock(xCoord + 1, yCoord + 1, zCoord + 2, Blocks.stonebrick, rand.nextInt(3), 2);
    world.setBlock(xCoord + 1, yCoord + 1, zCoord + 1, Blocks.stonebrick, rand.nextInt(3), 2);
    world.setBlock(xCoord + 2, yCoord + 1, zCoord + 5, Blocks.stonebrick, rand.nextInt(3), 2);
    world.setBlock(xCoord + 2, yCoord + 1, zCoord + 4, Blocks.stonebrick, rand.nextInt(3), 2);
    world.setBlock(xCoord + 2, yCoord + 1, zCoord + 3, Blocks.stonebrick, rand.nextInt(3), 2);
    world.setBlock(xCoord + 2, yCoord + 1, zCoord + 2, Blocks.stonebrick, rand.nextInt(3), 2);
    world.setBlock(xCoord + 2, yCoord + 1, zCoord + 1, Blocks.stonebrick, rand.nextInt(3), 2);
    world.setBlock(xCoord + 3, yCoord + 1, zCoord + 5, Blocks.stonebrick, rand.nextInt(3), 2);
    world.setBlock(xCoord + 3, yCoord + 1, zCoord + 4, Blocks.stonebrick, rand.nextInt(3), 2);
    world.setBlockToAir(xCoord + 3, yCoord + 1, zCoord + 3);
    world.setBlock(xCoord + 3, yCoord + 1, zCoord + 2, Blocks.stonebrick, rand.nextInt(3), 2);
    world.setBlock(xCoord + 3, yCoord + 1, zCoord + 1, Blocks.stonebrick, rand.nextInt(3), 2);
    world.setBlock(xCoord + 4, yCoord + 1, zCoord + 5, Blocks.stonebrick, rand.nextInt(3), 2);
    world.setBlock(xCoord + 4, yCoord + 1, zCoord + 4, Blocks.stone_slab, 5, 2);
    world.setBlockToAir(xCoord + 4, yCoord + 1, zCoord + 3);
    world.setBlock(xCoord + 4, yCoord + 1, zCoord + 2, Blocks.stonebrick, rand.nextInt(3), 2);
    world.setBlock(xCoord + 4, yCoord + 1, zCoord + 1, Blocks.stonebrick, rand.nextInt(3), 2);
    world.setBlock(xCoord + 5, yCoord + 1, zCoord + 5, Blocks.stonebrick, rand.nextInt(3), 2);
    world.setBlock(xCoord + 5, yCoord + 1, zCoord + 4, Blocks.stonebrick, rand.nextInt(3), 2);
    ItemDoor.placeDoorBlock(world, xCoord + 5, yCoord + 1, zCoord + 3, 0, Blocks.wooden_door);
    world.setBlock(xCoord + 5, yCoord + 1, zCoord + 2, Blocks.stonebrick, rand.nextInt(3), 2);
    world.setBlock(xCoord + 5, yCoord + 1, zCoord + 1, Blocks.stonebrick, rand.nextInt(3), 2);
    world.setBlock(xCoord + 1, yCoord + 2, zCoord + 5, Blocks.stonebrick, rand.nextInt(3), 2);
    world.setBlock(xCoord + 1, yCoord + 2, zCoord + 4, Blocks.stonebrick, rand.nextInt(3), 2);
    world.setBlock(xCoord + 1, yCoord + 2, zCoord + 3, Blocks.stonebrick, rand.nextInt(3), 2);
    world.setBlock(xCoord + 1, yCoord + 2, zCoord + 2, Blocks.stonebrick, rand.nextInt(3), 2);
    world.setBlock(xCoord + 1, yCoord + 2, zCoord + 1, Blocks.stonebrick, rand.nextInt(3), 2);
    world.setBlock(xCoord + 2, yCoord + 2, zCoord + 5, Blocks.stonebrick, rand.nextInt(3), 2);
    world.setBlock(xCoord + 2, yCoord + 2, zCoord + 4, Blocks.stone_slab, 5, 2);
    world.setBlock(xCoord + 2, yCoord + 2, zCoord + 3, Blocks.stonebrick, rand.nextInt(3), 2);
    world.setBlock(xCoord + 2, yCoord + 2, zCoord + 2, Blocks.stonebrick, rand.nextInt(3), 2);
    world.setBlock(xCoord + 2, yCoord + 2, zCoord + 1, Blocks.stonebrick, rand.nextInt(3), 2);
    world.setBlock(xCoord + 3, yCoord + 2, zCoord + 5, Blocks.stonebrick, rand.nextInt(3), 2);
    world.setBlockToAir(xCoord + 3, yCoord + 2, zCoord + 4);
    world.setBlockToAir(xCoord + 3, yCoord + 2, zCoord + 3);
    world.setBlock(xCoord + 3, yCoord + 2, zCoord + 2, Blocks.stonebrick, rand.nextInt(3), 2);
    world.setBlock(xCoord + 3, yCoord + 2, zCoord + 1, Blocks.stonebrick, rand.nextInt(3), 2);
    world.setBlock(xCoord + 4, yCoord + 2, zCoord + 5, Blocks.stonebrick, rand.nextInt(3), 2);
    world.setBlockToAir(xCoord + 4, yCoord + 2, zCoord + 4);
    world.setBlockToAir(xCoord + 4, yCoord + 2, zCoord + 3);
    world.setBlock(xCoord + 4, yCoord + 2, zCoord + 2, Blocks.stonebrick, rand.nextInt(3), 2);
    world.setBlock(xCoord + 4, yCoord + 2, zCoord + 1, Blocks.stonebrick, rand.nextInt(3), 2);
    world.setBlock(xCoord + 5, yCoord + 2, zCoord + 5, Blocks.stonebrick, rand.nextInt(3), 2);
    world.setBlock(xCoord + 5, yCoord + 2, zCoord + 4, Blocks.stonebrick, rand.nextInt(3), 2);
    world.setBlock(xCoord + 5, yCoord + 2, zCoord + 2, Blocks.stonebrick, rand.nextInt(3), 2);
    world.setBlock(xCoord + 5, yCoord + 2, zCoord + 1, Blocks.stonebrick, rand.nextInt(3), 2);
    world.setBlock(xCoord + 1, yCoord + 3, zCoord + 5, Blocks.stonebrick, rand.nextInt(3), 2);
    world.setBlock(xCoord + 1, yCoord + 3, zCoord + 4, Blocks.stonebrick, rand.nextInt(3), 2);
    world.setBlock(xCoord + 1, yCoord + 3, zCoord + 3, Blocks.stonebrick, rand.nextInt(3), 2);
    world.setBlock(xCoord + 1, yCoord + 3, zCoord + 2, Blocks.stonebrick, rand.nextInt(3), 2);
    world.setBlock(xCoord + 1, yCoord + 3, zCoord + 1, Blocks.stonebrick, rand.nextInt(3), 2);
    world.setBlock(xCoord + 2, yCoord + 3, zCoord + 5, Blocks.stonebrick, rand.nextInt(3), 2);
    world.setBlockToAir(xCoord + 2, yCoord + 3, zCoord + 4);
    world.setBlockToAir(xCoord + 2, yCoord + 3, zCoord + 3);
    world.setBlock(xCoord + 2, yCoord + 3, zCoord + 2, Blocks.stone_slab, 5, 2);
    world.setBlock(xCoord + 2, yCoord + 3, zCoord + 1, Blocks.stonebrick, rand.nextInt(3), 2);
    world.setBlock(xCoord + 3, yCoord + 3, zCoord + 5, Blocks.stonebrick, rand.nextInt(3), 2);
    world.setBlockToAir(xCoord + 3, yCoord + 3, zCoord + 4);
    world.setBlockToAir(xCoord + 3, yCoord + 3, zCoord + 3);
    world.setBlock(xCoord + 3, yCoord + 3, zCoord + 2, Blocks.stonebrick, rand.nextInt(3), 2);
    world.setBlock(xCoord + 3, yCoord + 3, zCoord + 1, Blocks.stonebrick, rand.nextInt(3), 2);
    world.setBlock(xCoord + 4, yCoord + 3, zCoord + 5, Blocks.stonebrick, rand.nextInt(3), 2);
    world.setBlockToAir(xCoord + 4, yCoord + 3, zCoord + 4);
    world.setBlockToAir(xCoord + 4, yCoord + 3, zCoord + 3);
    world.setBlock(xCoord + 4, yCoord + 3, zCoord + 2, Blocks.stonebrick, rand.nextInt(3), 2);
    world.setBlock(xCoord + 4, yCoord + 3, zCoord + 1, Blocks.stonebrick, rand.nextInt(3), 2);
    world.setBlock(xCoord + 5, yCoord + 3, zCoord + 5, Blocks.stonebrick, rand.nextInt(3), 2);
    world.setBlock(xCoord + 5, yCoord + 3, zCoord + 4, Blocks.stonebrick, rand.nextInt(3), 2);
    world.setBlock(xCoord + 5, yCoord + 3, zCoord + 3, Blocks.stonebrick, rand.nextInt(3), 2);
    world.setBlock(xCoord + 5, yCoord + 3, zCoord + 2, Blocks.stonebrick, rand.nextInt(3), 2);
    world.setBlock(xCoord + 5, yCoord + 3, zCoord + 1, Blocks.stonebrick, rand.nextInt(3), 2);
    world.setBlock(xCoord, yCoord + 4, zCoord + 3, Blocks.torch);
    world.setBlock(xCoord + 1, yCoord + 4, zCoord + 5, Blocks.stonebrick, rand.nextInt(3), 2);
    world.setBlock(xCoord + 1, yCoord + 4, zCoord + 4, Blocks.stonebrick, rand.nextInt(3), 2);
    world.setBlock(xCoord + 1, yCoord + 4, zCoord + 3, Blocks.stonebrick, rand.nextInt(3), 2);
    world.setBlock(xCoord + 1, yCoord + 4, zCoord + 2, Blocks.stonebrick, rand.nextInt(3), 2);
    world.setBlock(xCoord + 1, yCoord + 4, zCoord + 1, Blocks.stonebrick, rand.nextInt(3), 2);
    world.setBlock(xCoord + 2, yCoord + 4, zCoord + 5, Blocks.stonebrick, rand.nextInt(3), 2);
    world.setBlockToAir(xCoord + 2, yCoord + 4, zCoord + 4);
    world.setBlock(xCoord + 2, yCoord + 4, zCoord + 3, Blocks.torch);
    world.setBlockToAir(xCoord + 2, yCoord + 4, zCoord + 2);
    world.setBlock(xCoord + 2, yCoord + 4, zCoord + 1, Blocks.stonebrick, rand.nextInt(3), 2);
    world.setBlock(xCoord + 3, yCoord + 4, zCoord + 6, Blocks.torch);
    world.setBlock(xCoord + 3, yCoord + 4, zCoord + 5, Blocks.stonebrick, rand.nextInt(3), 2);
    world.setBlockToAir(xCoord + 3, yCoord + 4, zCoord + 4);
    world.setBlockToAir(xCoord + 3, yCoord + 4, zCoord + 3);
    world.setBlockToAir(xCoord + 3, yCoord + 4, zCoord + 2);
    world.setBlock(xCoord + 3, yCoord + 4, zCoord + 1, Blocks.stonebrick, rand.nextInt(3), 2);
    world.setBlock(xCoord + 3, yCoord + 4, zCoord, Blocks.torch);
    world.setBlock(xCoord + 4, yCoord + 4, zCoord + 5, Blocks.stonebrick, rand.nextInt(3), 2);
    world.setBlockToAir(xCoord + 4, yCoord + 4, zCoord + 4);
    world.setBlock(xCoord + 4, yCoord + 4, zCoord + 3, Blocks.stonebrick, rand.nextInt(3), 2);
    world.setBlock(xCoord + 4, yCoord + 4, zCoord + 2, Blocks.stone_slab, 5, 2);
    world.setBlock(xCoord + 4, yCoord + 4, zCoord + 1, Blocks.stonebrick, rand.nextInt(3), 2);
    world.setBlock(xCoord + 5, yCoord + 4, zCoord + 5, Blocks.stonebrick, rand.nextInt(3), 2);
    world.setBlock(xCoord + 5, yCoord + 4, zCoord + 4, Blocks.stonebrick, rand.nextInt(3), 2);
    world.setBlock(xCoord + 5, yCoord + 4, zCoord + 3, Blocks.stonebrick, rand.nextInt(3), 2);
    world.setBlock(xCoord + 5, yCoord + 4, zCoord + 2, Blocks.stonebrick, rand.nextInt(3), 2);
    world.setBlock(xCoord + 5, yCoord + 4, zCoord + 1, Blocks.stonebrick, rand.nextInt(3), 2);
    world.setBlock(xCoord + 6, yCoord + 4, zCoord + 3, Blocks.torch);
    world.setBlock(xCoord + 1, yCoord + 5, zCoord + 5, Blocks.stonebrick, rand.nextInt(3), 2);
    world.setBlock(xCoord + 1, yCoord + 5, zCoord + 4, Blocks.stonebrick, rand.nextInt(3), 2);
    world.setBlock(xCoord + 1, yCoord + 5, zCoord + 3, Blocks.stonebrick, rand.nextInt(3), 2);
    world.setBlock(xCoord + 1, yCoord + 5, zCoord + 2, Blocks.stonebrick, rand.nextInt(3), 2);
    world.setBlock(xCoord + 1, yCoord + 5, zCoord + 1, Blocks.stonebrick, rand.nextInt(3), 2);
    world.setBlock(xCoord + 2, yCoord + 5, zCoord + 5, Blocks.stonebrick, rand.nextInt(3), 2);
    world.setBlockToAir(xCoord + 2, yCoord + 5, zCoord + 4);
    world.setBlockToAir(xCoord + 2, yCoord + 5, zCoord + 3);
    world.setBlockToAir(xCoord + 2, yCoord + 5, zCoord + 2);
    world.setBlock(xCoord + 2, yCoord + 5, zCoord + 1, Blocks.stonebrick, rand.nextInt(3), 2);
    world.setBlock(xCoord + 3, yCoord + 5, zCoord + 5, Blocks.stonebrick, rand.nextInt(3), 2);
    world.setBlock(xCoord + 3, yCoord + 5, zCoord + 4, Blocks.stonebrick, rand.nextInt(3), 2);
    world.setBlockToAir(xCoord + 3, yCoord + 5, zCoord + 3);
    world.setBlockToAir(xCoord + 3, yCoord + 5, zCoord + 2);
    world.setBlock(xCoord + 3, yCoord + 5, zCoord + 1, Blocks.stonebrick, rand.nextInt(3), 2);
    world.setBlock(xCoord + 4, yCoord + 5, zCoord + 5, Blocks.stonebrick, rand.nextInt(3), 2);
    world.setBlock(xCoord + 4, yCoord + 5, zCoord + 4, Blocks.stone_slab, 5, 2);
    world.setBlockToAir(xCoord + 4, yCoord + 5, zCoord + 3);
    world.setBlockToAir(xCoord + 4, yCoord + 5, zCoord + 2);
    world.setBlock(xCoord + 4, yCoord + 5, zCoord + 1, Blocks.stonebrick, rand.nextInt(3), 2);
    world.setBlock(xCoord + 5, yCoord + 5, zCoord + 5, Blocks.stonebrick, rand.nextInt(3), 2);
    world.setBlock(xCoord + 5, yCoord + 5, zCoord + 4, Blocks.stonebrick, rand.nextInt(3), 2);
    world.setBlock(xCoord + 5, yCoord + 5, zCoord + 3, Blocks.stonebrick, rand.nextInt(3), 2);
    world.setBlock(xCoord + 5, yCoord + 5, zCoord + 2, Blocks.stonebrick, rand.nextInt(3), 2);
    world.setBlock(xCoord + 5, yCoord + 5, zCoord + 1, Blocks.stonebrick, rand.nextInt(3), 2);
    world.setBlock(xCoord + 1, yCoord + 6, zCoord + 5, Blocks.stonebrick, rand.nextInt(3), 2);
    world.setBlock(xCoord + 1, yCoord + 6, zCoord + 4, Blocks.stonebrick, rand.nextInt(3), 2);
    world.setBlock(xCoord + 1, yCoord + 6, zCoord + 3, Blocks.stonebrick, rand.nextInt(3), 2);
    world.setBlock(xCoord + 1, yCoord + 6, zCoord + 2, Blocks.stonebrick, rand.nextInt(3), 2);
    world.setBlock(xCoord + 1, yCoord + 6, zCoord + 1, Blocks.stonebrick, rand.nextInt(3), 2);
    world.setBlock(xCoord + 2, yCoord + 6, zCoord + 5, Blocks.stonebrick, rand.nextInt(3), 2);
    world.setBlock(xCoord + 2, yCoord + 6, zCoord + 4, Blocks.stone_slab, 5, 2);
    world.setBlock(xCoord + 2, yCoord + 6, zCoord + 3, Blocks.stonebrick, rand.nextInt(3), 2);
    world.setBlockToAir(xCoord + 2, yCoord + 6, zCoord + 2);
    world.setBlock(xCoord + 2, yCoord + 6, zCoord + 1, Blocks.stonebrick, rand.nextInt(3), 2);
    world.setBlock(xCoord + 3, yCoord + 6, zCoord + 5, Blocks.stonebrick, rand.nextInt(3), 2);
    world.setBlockToAir(xCoord + 3, yCoord + 6, zCoord + 4);
    world.setBlockToAir(xCoord + 3, yCoord + 6, zCoord + 3);
    world.setBlockToAir(xCoord + 3, yCoord + 6, zCoord + 2);
    world.setBlock(xCoord + 3, yCoord + 6, zCoord + 1, Blocks.stonebrick, rand.nextInt(3), 2);
    world.setBlock(xCoord + 4, yCoord + 6, zCoord + 5, Blocks.stonebrick, rand.nextInt(3), 2);
    world.setBlockToAir(xCoord + 4, yCoord + 6, zCoord + 4);
    world.setBlock(xCoord + 4, yCoord + 6, zCoord + 3, Blocks.torch);
    world.setBlockToAir(xCoord + 4, yCoord + 6, zCoord + 2);
    world.setBlock(xCoord + 4, yCoord + 6, zCoord + 1, Blocks.stonebrick, rand.nextInt(3), 2);
    world.setBlock(xCoord + 5, yCoord + 6, zCoord + 5, Blocks.stonebrick, rand.nextInt(3), 2);
    world.setBlock(xCoord + 5, yCoord + 6, zCoord + 4, Blocks.stonebrick, rand.nextInt(3), 2);
    world.setBlock(xCoord + 5, yCoord + 6, zCoord + 3, Blocks.stonebrick, rand.nextInt(3), 2);
    world.setBlock(xCoord + 5, yCoord + 6, zCoord + 2, Blocks.stonebrick, rand.nextInt(3), 2);
    world.setBlock(xCoord + 5, yCoord + 6, zCoord + 1, Blocks.stonebrick, rand.nextInt(3), 2);
    world.setBlock(xCoord + 1, yCoord + 7, zCoord + 5, Blocks.stonebrick, rand.nextInt(3), 2);
    world.setBlock(xCoord + 1, yCoord + 7, zCoord + 4, Blocks.stonebrick, rand.nextInt(3), 2);
    world.setBlock(xCoord + 1, yCoord + 7, zCoord + 3, Blocks.stonebrick, rand.nextInt(3), 2);
    world.setBlock(xCoord + 1, yCoord + 7, zCoord + 2, Blocks.stonebrick, rand.nextInt(3), 2);
    world.setBlock(xCoord + 1, yCoord + 7, zCoord + 1, Blocks.stonebrick, rand.nextInt(3), 2);
    world.setBlock(xCoord + 2, yCoord + 7, zCoord + 5, Blocks.stonebrick, rand.nextInt(3), 2);
    world.setBlockToAir(xCoord + 2, yCoord + 7, zCoord + 4);
    world.setBlockToAir(xCoord + 2, yCoord + 7, zCoord + 3);
    world.setBlock(xCoord + 2, yCoord + 7, zCoord + 2, Blocks.stone_slab, 5, 2);
    world.setBlock(xCoord + 2, yCoord + 7, zCoord + 1, Blocks.stonebrick, rand.nextInt(3), 2);
    world.setBlock(xCoord + 3, yCoord + 7, zCoord + 5, Blocks.stonebrick, rand.nextInt(3), 2);
    world.setBlockToAir(xCoord + 3, yCoord + 7, zCoord + 4);
    world.setBlockToAir(xCoord + 3, yCoord + 7, zCoord + 3);
    world.setBlock(xCoord + 3, yCoord + 7, zCoord + 2, Blocks.stonebrick, rand.nextInt(3), 2);
    world.setBlock(xCoord + 3, yCoord + 7, zCoord + 1, Blocks.stonebrick, rand.nextInt(3), 2);
    world.setBlock(xCoord + 4, yCoord + 7, zCoord + 5, Blocks.stonebrick, rand.nextInt(3), 2);
    world.setBlockToAir(xCoord + 4, yCoord + 7, zCoord + 4);
    world.setBlockToAir(xCoord + 4, yCoord + 7, zCoord + 3);
    world.setBlockToAir(xCoord + 4, yCoord + 7, zCoord + 2);
    world.setBlock(xCoord + 4, yCoord + 7, zCoord + 1, Blocks.stonebrick, rand.nextInt(3), 2);
    world.setBlock(xCoord + 5, yCoord + 7, zCoord + 5, Blocks.stonebrick, rand.nextInt(3), 2);
    world.setBlock(xCoord + 5, yCoord + 7, zCoord + 4, Blocks.stonebrick, rand.nextInt(3), 2);
    world.setBlock(xCoord + 5, yCoord + 7, zCoord + 3, Blocks.stonebrick, rand.nextInt(3), 2);
    world.setBlock(xCoord + 5, yCoord + 7, zCoord + 2, Blocks.stonebrick, rand.nextInt(3), 2);
    world.setBlock(xCoord + 5, yCoord + 7, zCoord + 1, Blocks.stonebrick, rand.nextInt(3), 2);
    world.setBlock(xCoord + 1, yCoord + 8, zCoord + 5, Blocks.stonebrick, rand.nextInt(3), 2);
    world.setBlock(xCoord + 1, yCoord + 8, zCoord + 4, Blocks.stonebrick, rand.nextInt(3), 2);
    world.setBlock(xCoord + 1, yCoord + 8, zCoord + 3, Blocks.stonebrick, rand.nextInt(3), 2);
    world.setBlock(xCoord + 1, yCoord + 8, zCoord + 2, Blocks.stonebrick, rand.nextInt(3), 2);
    world.setBlock(xCoord + 1, yCoord + 8, zCoord + 1, Blocks.stonebrick, rand.nextInt(3), 2);
    world.setBlock(xCoord + 2, yCoord + 8, zCoord + 5, Blocks.stonebrick, rand.nextInt(3), 2);
    world.setBlockToAir(xCoord + 2, yCoord + 8, zCoord + 4);
    world.setBlock(xCoord + 2, yCoord + 8, zCoord + 3, Blocks.torch);
    world.setBlockToAir(xCoord + 2, yCoord + 8, zCoord + 2);
    world.setBlock(xCoord + 2, yCoord + 8, zCoord + 1, Blocks.stonebrick, rand.nextInt(3), 2);
    world.setBlock(xCoord + 3, yCoord + 8, zCoord + 5, Blocks.stonebrick, rand.nextInt(3), 2);
    world.setBlockToAir(xCoord + 3, yCoord + 8, zCoord + 4);
    world.setBlockToAir(xCoord + 3, yCoord + 8, zCoord + 3);
    world.setBlockToAir(xCoord + 3, yCoord + 8, zCoord + 2);
    world.setBlock(xCoord + 3, yCoord + 8, zCoord + 1, Blocks.stonebrick, rand.nextInt(3), 2);
    world.setBlock(xCoord + 4, yCoord + 8, zCoord + 5, Blocks.stonebrick, rand.nextInt(3), 2);
    world.setBlockToAir(xCoord + 4, yCoord + 8, zCoord + 4);
    world.setBlock(xCoord + 4, yCoord + 8, zCoord + 3, Blocks.stonebrick, rand.nextInt(3), 2);
    world.setBlock(xCoord + 4, yCoord + 8, zCoord + 2, Blocks.stone_slab, 5, 2);
    world.setBlock(xCoord + 4, yCoord + 8, zCoord + 1, Blocks.stonebrick, rand.nextInt(3), 2);
    world.setBlock(xCoord + 5, yCoord + 8, zCoord + 5, Blocks.stonebrick, rand.nextInt(3), 2);
    world.setBlock(xCoord + 5, yCoord + 8, zCoord + 4, Blocks.stonebrick, rand.nextInt(3), 2);
    world.setBlock(xCoord + 5, yCoord + 8, zCoord + 3, Blocks.stonebrick, rand.nextInt(3), 2);
    world.setBlock(xCoord + 5, yCoord + 8, zCoord + 2, Blocks.stonebrick, rand.nextInt(3), 2);
    world.setBlock(xCoord + 5, yCoord + 8, zCoord + 1, Blocks.stonebrick, rand.nextInt(3), 2);
    world.setBlock(xCoord + 1, yCoord + 9, zCoord + 5, Blocks.stonebrick, rand.nextInt(3), 2);
    world.setBlock(xCoord + 1, yCoord + 9, zCoord + 4, Blocks.stonebrick, rand.nextInt(3), 2);
    world.setBlock(xCoord + 1, yCoord + 9, zCoord + 3, Blocks.stonebrick, rand.nextInt(3), 2);
    world.setBlock(xCoord + 1, yCoord + 9, zCoord + 2, Blocks.stonebrick, rand.nextInt(3), 2);
    world.setBlock(xCoord + 1, yCoord + 9, zCoord + 1, Blocks.stonebrick, rand.nextInt(3), 2);
    world.setBlock(xCoord + 2, yCoord + 9, zCoord + 5, Blocks.stonebrick, rand.nextInt(3), 2);
    world.setBlockToAir(xCoord + 2, yCoord + 9, zCoord + 4);
    world.setBlockToAir(xCoord + 2, yCoord + 9, zCoord + 3);
    world.setBlockToAir(xCoord + 2, yCoord + 9, zCoord + 2);
    world.setBlock(xCoord + 2, yCoord + 9, zCoord + 1, Blocks.stonebrick, rand.nextInt(3), 2);
    world.setBlock(xCoord + 3, yCoord + 9, zCoord + 5, Blocks.stonebrick, rand.nextInt(3), 2);
    world.setBlock(xCoord + 3, yCoord + 9, zCoord + 4, Blocks.stonebrick, rand.nextInt(3), 2);
    world.setBlockToAir(xCoord + 3, yCoord + 9, zCoord + 3);
    world.setBlockToAir(xCoord + 3, yCoord + 9, zCoord + 2);
    world.setBlock(xCoord + 3, yCoord + 9, zCoord + 1, Blocks.stonebrick, rand.nextInt(3), 2);
    world.setBlock(xCoord + 4, yCoord + 9, zCoord + 5, Blocks.stonebrick, rand.nextInt(3), 2);
    world.setBlock(xCoord + 4, yCoord + 9, zCoord + 4, Blocks.stone_slab, 5, 2);
    world.setBlockToAir(xCoord + 4, yCoord + 9, zCoord + 3);
    world.setBlockToAir(xCoord + 4, yCoord + 9, zCoord + 2);
    world.setBlock(xCoord + 4, yCoord + 9, zCoord + 1, Blocks.stonebrick, rand.nextInt(3), 2);
    world.setBlock(xCoord + 5, yCoord + 9, zCoord + 5, Blocks.stonebrick, rand.nextInt(3), 2);
    world.setBlock(xCoord + 5, yCoord + 9, zCoord + 4, Blocks.stonebrick, rand.nextInt(3), 2);
    world.setBlock(xCoord + 5, yCoord + 9, zCoord + 3, Blocks.stonebrick, rand.nextInt(3), 2);
    world.setBlock(xCoord + 5, yCoord + 9, zCoord + 2, Blocks.stonebrick, rand.nextInt(3), 2);
    world.setBlock(xCoord + 5, yCoord + 9, zCoord + 1, Blocks.stonebrick, rand.nextInt(3), 2);
    world.setBlock(xCoord, yCoord + 10, zCoord + 6, Blocks.stonebrick, rand.nextInt(3), 2);
    world.setBlock(xCoord, yCoord + 10, zCoord + 5, Blocks.stonebrick, rand.nextInt(3), 2);
    world.setBlock(xCoord, yCoord + 10, zCoord + 4, Blocks.stonebrick, rand.nextInt(3), 2);
    world.setBlock(xCoord, yCoord + 10, zCoord + 3, Blocks.stonebrick, rand.nextInt(3), 2);
    world.setBlock(xCoord, yCoord + 10, zCoord + 2, Blocks.stonebrick, rand.nextInt(3), 2);
    world.setBlock(xCoord, yCoord + 10, zCoord + 1, Blocks.stonebrick, rand.nextInt(3), 2);
    world.setBlock(xCoord, yCoord + 10, zCoord, Blocks.stonebrick, rand.nextInt(3), 2);
    world.setBlock(xCoord + 1, yCoord + 10, zCoord + 6, Blocks.stonebrick, rand.nextInt(3), 2);
    world.setBlock(xCoord + 1, yCoord + 10, zCoord + 5, Blocks.stonebrick, rand.nextInt(3), 2);
    world.setBlock(xCoord + 1, yCoord + 10, zCoord + 4, Blocks.stonebrick, rand.nextInt(3), 2);
    world.setBlock(xCoord + 1, yCoord + 10, zCoord + 3, Blocks.stonebrick, rand.nextInt(3), 2);
    world.setBlock(xCoord + 1, yCoord + 10, zCoord + 2, Blocks.stonebrick, rand.nextInt(3), 2);
    world.setBlock(xCoord + 1, yCoord + 10, zCoord + 1, Blocks.stonebrick, rand.nextInt(3), 2);
    world.setBlock(xCoord + 1, yCoord + 10, zCoord, Blocks.stonebrick, rand.nextInt(3), 2);
    world.setBlock(xCoord + 2, yCoord + 10, zCoord + 6, Blocks.stonebrick, rand.nextInt(3), 2);
    world.setBlock(xCoord + 2, yCoord + 10, zCoord + 5, Blocks.stonebrick, rand.nextInt(3), 2);
    world.setBlock(xCoord + 2, yCoord + 10, zCoord + 4, Blocks.stone_slab, 5, 2);
    world.setBlock(xCoord + 2, yCoord + 10, zCoord + 3, Blocks.stonebrick, rand.nextInt(3), 2);
    world.setBlock(xCoord + 2, yCoord + 10, zCoord + 2, Blocks.stonebrick, rand.nextInt(3), 2);
    world.setBlock(xCoord + 2, yCoord + 10, zCoord + 1, Blocks.stonebrick, rand.nextInt(3), 2);
    world.setBlock(xCoord + 2, yCoord + 10, zCoord, Blocks.stonebrick, rand.nextInt(3), 2);
    world.setBlock(xCoord + 3, yCoord + 10, zCoord + 6, Blocks.stonebrick, rand.nextInt(3), 2);
    world.setBlock(xCoord + 3, yCoord + 10, zCoord + 5, Blocks.stonebrick, rand.nextInt(3), 2);
    world.setBlockToAir(xCoord + 3, yCoord + 10, zCoord + 4);
    world.setBlockToAir(xCoord + 3, yCoord + 10, zCoord + 3);
    world.setBlockToAir(xCoord + 3, yCoord + 10, zCoord + 2);
    world.setBlock(xCoord + 3, yCoord + 10, zCoord + 1, Blocks.stonebrick, rand.nextInt(3), 2);
    world.setBlock(xCoord + 3, yCoord + 10, zCoord, Blocks.stonebrick, rand.nextInt(3), 2);
    world.setBlock(xCoord + 4, yCoord + 10, zCoord + 6, Blocks.stonebrick, rand.nextInt(3), 2);
    world.setBlock(xCoord + 4, yCoord + 10, zCoord + 5, Blocks.stonebrick, rand.nextInt(3), 2);
    world.setBlockToAir(xCoord + 4, yCoord + 10, zCoord + 4);
    world.setBlockToAir(xCoord + 4, yCoord + 10, zCoord + 3);
    world.setBlockToAir(xCoord + 4, yCoord + 10, zCoord + 2);
    world.setBlock(xCoord + 4, yCoord + 10, zCoord + 1, Blocks.stonebrick, rand.nextInt(3), 2);
    world.setBlock(xCoord + 4, yCoord + 10, zCoord, Blocks.stonebrick, rand.nextInt(3), 2);
    world.setBlock(xCoord + 5, yCoord + 10, zCoord + 6, Blocks.stonebrick, rand.nextInt(3), 2);
    world.setBlock(xCoord + 5, yCoord + 10, zCoord + 5, Blocks.stonebrick, rand.nextInt(3), 2);
    world.setBlock(xCoord + 5, yCoord + 10, zCoord + 4, Blocks.stonebrick, rand.nextInt(3), 2);
    world.setBlock(xCoord + 5, yCoord + 10, zCoord + 3, Blocks.stonebrick, rand.nextInt(3), 2);
    world.setBlock(xCoord + 5, yCoord + 10, zCoord + 2, Blocks.stonebrick, rand.nextInt(3), 2);
    world.setBlock(xCoord + 5, yCoord + 10, zCoord + 1, Blocks.stonebrick, rand.nextInt(3), 2);
    world.setBlock(xCoord + 5, yCoord + 10, zCoord, Blocks.stonebrick, rand.nextInt(3), 2);
    world.setBlock(xCoord + 6, yCoord + 10, zCoord + 6, Blocks.stonebrick, rand.nextInt(3), 2);
    world.setBlock(xCoord + 6, yCoord + 10, zCoord + 5, Blocks.stonebrick, rand.nextInt(3), 2);
    world.setBlock(xCoord + 6, yCoord + 10, zCoord + 4, Blocks.stonebrick, rand.nextInt(3), 2);
    world.setBlock(xCoord + 6, yCoord + 10, zCoord + 3, Blocks.stonebrick, rand.nextInt(3), 2);
    world.setBlock(xCoord + 6, yCoord + 10, zCoord + 2, Blocks.stonebrick, rand.nextInt(3), 2);
    world.setBlock(xCoord + 6, yCoord + 10, zCoord + 1, Blocks.stonebrick, rand.nextInt(3), 2);
    world.setBlock(xCoord + 6, yCoord + 10, zCoord, Blocks.stonebrick, rand.nextInt(3), 2);
    world.setBlock(xCoord, yCoord + 11, zCoord + 6, Blocks.stonebrick, rand.nextInt(3), 2);
    world.setBlock(xCoord, yCoord + 11, zCoord + 4, Blocks.stonebrick, rand.nextInt(3), 2);
    world.setBlock(xCoord, yCoord + 11, zCoord + 2, Blocks.stonebrick, rand.nextInt(3), 2);
    world.setBlock(xCoord, yCoord + 11, zCoord, Blocks.stonebrick, rand.nextInt(3), 2);
    world.setBlockToAir(xCoord + 1, yCoord + 11, zCoord + 5);
    world.setBlockToAir(xCoord + 1, yCoord + 11, zCoord + 4);
    world.setBlockToAir(xCoord + 1, yCoord + 11, zCoord + 3);
    world.setBlockToAir(xCoord + 1, yCoord + 11, zCoord + 2);
    world.setBlockToAir(xCoord + 1, yCoord + 11, zCoord + 1);
    world.setBlock(xCoord + 2, yCoord + 11, zCoord + 6, Blocks.stonebrick, rand.nextInt(3), 2);
    world.setBlockToAir(xCoord + 2, yCoord + 11, zCoord + 5);
    world.setBlockToAir(xCoord + 2, yCoord + 11, zCoord + 4);
    world.setBlockToAir(xCoord + 2, yCoord + 11, zCoord + 3);
    world.setBlockToAir(xCoord + 2, yCoord + 11, zCoord + 2);
    world.setBlockToAir(xCoord + 2, yCoord + 11, zCoord + 1);
    world.setBlock(xCoord + 2, yCoord + 11, zCoord, Blocks.stonebrick, rand.nextInt(3), 2);
    world.setBlockToAir(xCoord + 3, yCoord + 11, zCoord + 5);
    world.setBlockToAir(xCoord + 3, yCoord + 11, zCoord + 4);
    world.setBlockToAir(xCoord + 3, yCoord + 11, zCoord + 3);
    world.setBlockToAir(xCoord + 3, yCoord + 11, zCoord + 2);
    world.setBlockToAir(xCoord + 3, yCoord + 11, zCoord + 1);
    world.setBlock(xCoord + 4, yCoord + 11, zCoord + 6, Blocks.stonebrick, rand.nextInt(3), 2);
    world.setBlockToAir(xCoord + 4, yCoord + 11, zCoord + 5);
    world.setBlockToAir(xCoord + 4, yCoord + 11, zCoord + 4);
    world.setBlockToAir(xCoord + 4, yCoord + 11, zCoord + 3);
    world.setBlockToAir(xCoord + 4, yCoord + 11, zCoord + 2);
    world.setBlockToAir(xCoord + 4, yCoord + 11, zCoord + 1);
    world.setBlock(xCoord + 4, yCoord + 11, zCoord, Blocks.stonebrick, rand.nextInt(3), 2);

    Block chest = ModBlocks.chestLoot;
    world.setBlock(xCoord + 5, yCoord + 11, zCoord + 5, chest);
    TileEntity tileentitychest = world.getTileEntity(xCoord + 5, yCoord + 11, zCoord + 5);
    if (tileentitychest != null) {
      WeightedRandomChestContent.generateChestContents(rand, LootManager.loot, (TileEntityChest)tileentitychest, rand.nextInt(5) + 1);
    }
    ChatHandler.logDebug("Day Z Fort Chest Created At " + (xCoord + 5) + ", " + (yCoord + 11) + ", " + (zCoord + 5) + ".");

    world.setBlockToAir(xCoord + 5, yCoord + 11, zCoord + 4);
    world.setBlockToAir(xCoord + 5, yCoord + 11, zCoord + 3);
    world.setBlockToAir(xCoord + 5, yCoord + 11, zCoord + 2);
    world.setBlockToAir(xCoord + 5, yCoord + 11, zCoord + 1);
    world.setBlock(xCoord + 6, yCoord + 11, zCoord + 6, Blocks.stonebrick, rand.nextInt(3), 2);
    world.setBlock(xCoord + 6, yCoord + 11, zCoord + 4, Blocks.stonebrick, rand.nextInt(3), 2);
    world.setBlock(xCoord + 6, yCoord + 11, zCoord + 2, Blocks.stonebrick, rand.nextInt(3), 2);
    world.setBlock(xCoord + 6, yCoord + 11, zCoord, Blocks.stonebrick, rand.nextInt(3), 2);
    world.setBlock(xCoord, yCoord + 12, zCoord + 6, Blocks.torch);
    world.setBlock(xCoord, yCoord + 12, zCoord + 4, Blocks.torch);
    world.setBlock(xCoord, yCoord + 12, zCoord + 2, Blocks.torch);
    world.setBlock(xCoord, yCoord + 12, zCoord, Blocks.torch);
    world.setBlock(xCoord + 2, yCoord + 12, zCoord + 6, Blocks.torch);
    world.setBlock(xCoord + 2, yCoord + 12, zCoord, Blocks.torch);
    world.setBlock(xCoord + 4, yCoord + 12, zCoord + 6, Blocks.torch);
    world.setBlock(xCoord + 4, yCoord + 12, zCoord, Blocks.torch);
    world.setBlock(xCoord + 6, yCoord + 12, zCoord + 6, Blocks.torch);
    world.setBlock(xCoord + 6, yCoord + 12, zCoord + 4, Blocks.torch);
    world.setBlock(xCoord + 6, yCoord + 12, zCoord + 2, Blocks.torch);
    world.setBlock(xCoord + 6, yCoord + 12, zCoord, Blocks.torch);
    return true;
  }*/

  @Override
  public boolean generate(World world, Random rand, BlockPos pos) {
    return false;
  }
}