package com.github.dayzminecraft.dayzminecraft.common.world.generation.structures;

import net.minecraft.init.Blocks;
import net.minecraft.item.ItemDoor;
import net.minecraft.util.BlockPos;
import net.minecraft.util.EnumFacing;
import net.minecraft.world.World;

import java.util.Random;

public class StructureHouse extends Structure {

  @Override
  public boolean generate(World world, Random rand, BlockPos pos) {
    world.setBlockState(pos.add(1, 0, 9), Blocks.cobblestone.getDefaultState());
    world.setBlockState(pos.add(1, 0, 9), Blocks.cobblestone.getDefaultState());
    world.setBlockState(pos.add(1, 0, 8), Blocks.cobblestone.getDefaultState());
    world.setBlockState(pos.add(1, 0, 7), Blocks.cobblestone.getDefaultState());
    world.setBlockState(pos.add(1, 0, 6), Blocks.cobblestone.getDefaultState());
    world.setBlockState(pos.add(1, 0, 5), Blocks.cobblestone.getDefaultState());
    world.setBlockState(pos.add(1, 0, 4), Blocks.cobblestone.getDefaultState());
    world.setBlockState(pos.add(1, 0, 3), Blocks.cobblestone.getDefaultState());
    world.setBlockState(pos.add(1, 0, 2), Blocks.cobblestone.getDefaultState());
    world.setBlockState(pos.add(1, 0, 1), Blocks.cobblestone.getDefaultState());
    world.setBlockState(pos.add(2, 0, 9), Blocks.cobblestone.getDefaultState());
    world.setBlockState(pos.add(2, 0, 8), Blocks.planks.getDefaultState());
    world.setBlockState(pos.add(2, 0, 7), Blocks.planks.getDefaultState());
    world.setBlockState(pos.add(2, 0, 6), Blocks.planks.getDefaultState());
    world.setBlockState(pos.add(2, 0, 5), Blocks.planks.getDefaultState());
    world.setBlockState(pos.add(2, 0, 4), Blocks.planks.getDefaultState());
    world.setBlockState(pos.add(2, 0, 3), Blocks.planks.getDefaultState());
    world.setBlockState(pos.add(2, 0, 2), Blocks.planks.getDefaultState());
    world.setBlockState(pos.add(2, 0, 1), Blocks.cobblestone.getDefaultState());
    world.setBlockState(pos.add(3, 0, 9), Blocks.cobblestone.getDefaultState());
    world.setBlockState(pos.add(3, 0, 8), Blocks.planks.getDefaultState());
    world.setBlockState(pos.add(3, 0, 7), Blocks.planks.getDefaultState());
    world.setBlockState(pos.add(3, 0, 6), Blocks.planks.getDefaultState());
    world.setBlockState(pos.add(3, 0, 5), Blocks.planks.getDefaultState());
    world.setBlockState(pos.add(3, 0, 4), Blocks.planks.getDefaultState());
    world.setBlockState(pos.add(3, 0, 3), Blocks.planks.getDefaultState());
    world.setBlockState(pos.add(3, 0, 2), Blocks.planks.getDefaultState());
    world.setBlockState(pos.add(3, 0, 1), Blocks.cobblestone.getDefaultState());
    world.setBlockState(pos.add(4, 0, 9), Blocks.cobblestone.getDefaultState());
    world.setBlockState(pos.add(4, 0, 8), Blocks.planks.getDefaultState());
    world.setBlockState(pos.add(4, 0, 7), Blocks.planks.getDefaultState());
    world.setBlockState(pos.add(4, 0, 6), Blocks.planks.getDefaultState());
    world.setBlockState(pos.add(4, 0, 5), Blocks.planks.getDefaultState());
    world.setBlockState(pos.add(4, 0, 4), Blocks.planks.getDefaultState());
    world.setBlockState(pos.add(4, 0, 3), Blocks.planks.getDefaultState());
    world.setBlockState(pos.add(4, 0, 2), Blocks.planks.getDefaultState());
    world.setBlockState(pos.add(4, 0, 1), Blocks.cobblestone.getDefaultState());
    world.setBlockState(pos.add(5, 0, 9), Blocks.cobblestone.getDefaultState());
    world.setBlockState(pos.add(5, 0, 8), Blocks.planks.getDefaultState());
    world.setBlockState(pos.add(5, 0, 7), Blocks.planks.getDefaultState());
    world.setBlockState(pos.add(5, 0, 6), Blocks.planks.getDefaultState());
    world.setBlockState(pos.add(5, 0, 5), Blocks.planks.getDefaultState());
    world.setBlockState(pos.add(5, 0, 4), Blocks.planks.getDefaultState());
    world.setBlockState(pos.add(5, 0, 3), Blocks.planks.getDefaultState());
    world.setBlockState(pos.add(5, 0, 2), Blocks.planks.getDefaultState());
    world.setBlockState(pos.add(5, 0, 1), Blocks.cobblestone.getDefaultState());
    world.setBlockState(pos.add(6, 0, 9), Blocks.cobblestone.getDefaultState());
    world.setBlockState(pos.add(6, 0, 8), Blocks.planks.getDefaultState());
    world.setBlockState(pos.add(6, 0, 7), Blocks.planks.getDefaultState());
    world.setBlockState(pos.add(6, 0, 6), Blocks.planks.getDefaultState());
    world.setBlockState(pos.add(6, 0, 5), Blocks.planks.getDefaultState());
    world.setBlockState(pos.add(6, 0, 4), Blocks.planks.getDefaultState());
    world.setBlockState(pos.add(6, 0, 3), Blocks.planks.getDefaultState());
    world.setBlockState(pos.add(6, 0, 2), Blocks.planks.getDefaultState());
    world.setBlockState(pos.add(6, 0, 1), Blocks.cobblestone.getDefaultState());
    world.setBlockState(pos.add(7, 0, 9), Blocks.cobblestone.getDefaultState());
    world.setBlockState(pos.add(7, 0, 8), Blocks.planks.getDefaultState());
    world.setBlockState(pos.add(7, 0, 7), Blocks.planks.getDefaultState());
    world.setBlockState(pos.add(7, 0, 6), Blocks.planks.getDefaultState());
    world.setBlockState(pos.add(7, 0, 5), Blocks.planks.getDefaultState());
    world.setBlockState(pos.add(7, 0, 4), Blocks.planks.getDefaultState());
    world.setBlockState(pos.add(7, 0, 3), Blocks.planks.getDefaultState());
    world.setBlockState(pos.add(7, 0, 2), Blocks.planks.getDefaultState());
    world.setBlockState(pos.add(7, 0, 1), Blocks.cobblestone.getDefaultState());
    world.setBlockState(pos.add(8, 0, 9), Blocks.cobblestone.getDefaultState());
    world.setBlockState(pos.add(8, 0, 8), Blocks.planks.getDefaultState());
    world.setBlockState(pos.add(8, 0, 7), Blocks.planks.getDefaultState());
    world.setBlockState(pos.add(8, 0, 6), Blocks.planks.getDefaultState());
    world.setBlockState(pos.add(8, 0, 5), Blocks.planks.getDefaultState());
    world.setBlockState(pos.add(8, 0, 4), Blocks.planks.getDefaultState());
    world.setBlockState(pos.add(8, 0, 3), Blocks.planks.getDefaultState());
    world.setBlockState(pos.add(8, 0, 2), Blocks.planks.getDefaultState());
    world.setBlockState(pos.add(8, 0, 1), Blocks.cobblestone.getDefaultState());
    world.setBlockState(pos.add(9, 0, 9), Blocks.cobblestone.getDefaultState());
    world.setBlockState(pos.add(9, 0, 8), Blocks.cobblestone.getDefaultState());
    world.setBlockState(pos.add(9, 0, 7), Blocks.cobblestone.getDefaultState());
    world.setBlockState(pos.add(9, 0, 6), Blocks.cobblestone.getDefaultState());
    world.setBlockState(pos.add(9, 0, 5), Blocks.cobblestone.getDefaultState());
    world.setBlockState(pos.add(9, 0, 4), Blocks.cobblestone.getDefaultState());
    world.setBlockState(pos.add(9, 0, 3), Blocks.cobblestone.getDefaultState());
    world.setBlockState(pos.add(9, 0, 2), Blocks.cobblestone.getDefaultState());
    world.setBlockState(pos.add(9, 0, 1), Blocks.cobblestone.getDefaultState());
    world.setBlockState(pos.add(1, 1, 9), Blocks.log.getDefaultState());
    world.setBlockState(pos.add(1, 1, 8), Blocks.planks.getDefaultState());
    world.setBlockState(pos.add(1, 1, 7), Blocks.planks.getDefaultState());
    world.setBlockState(pos.add(1, 1, 6), Blocks.planks.getDefaultState());
    ItemDoor.placeDoor(world, pos.add(1, 1, 5), EnumFacing.NORTH, Blocks.oak_door);
    world.setBlockState(pos.add(1, 1, 4), Blocks.planks.getDefaultState());
    world.setBlockState(pos.add(1, 1, 3), Blocks.planks.getDefaultState());
    world.setBlockState(pos.add(1, 1, 2), Blocks.planks.getDefaultState());
    world.setBlockState(pos.add(1, 1, 1), Blocks.log.getDefaultState());
    world.setBlockState(pos.add(2, 1, 9), Blocks.planks.getDefaultState());
    world.setBlockToAir(pos.add(2, 1, 8));
    world.setBlockToAir(pos.add(2, 1, 7));
    world.setBlockToAir(pos.add(2, 1, 6));
    world.setBlockToAir(pos.add(2, 1, 5));
    world.setBlockToAir(pos.add(2, 1, 4));
    world.setBlockToAir(pos.add(2, 1, 3));
    world.setBlockState(pos.add(2, 1, 2), Blocks.bookshelf.getDefaultState());
    world.setBlockState(pos.add(2, 1, 1), Blocks.planks.getDefaultState());
    world.setBlockState(pos.add(3, 1, 9), Blocks.planks.getDefaultState());
    world.setBlockToAir(pos.add(3, 1, 8));
    world.setBlockState(pos.add(3, 1, 7), Blocks.birch_fence.getDefaultState());
    world.setBlockToAir(pos.add(3, 1, 6));
    world.setBlockToAir(pos.add(3, 1, 5));
    world.setBlockToAir(pos.add(3, 1, 4));
    world.setBlockToAir(pos.add(3, 1, 3));
    world.setBlockState(pos.add(3, 1, 2), Blocks.bookshelf.getDefaultState());
    world.setBlockState(pos.add(3, 1, 1), Blocks.planks.getDefaultState());
    world.setBlockState(pos.add(4, 1, 9), Blocks.planks.getDefaultState());
    world.setBlockToAir(pos.add(4, 1, 8));
    world.setBlockToAir(pos.add(4, 1, 7));
    world.setBlockToAir(pos.add(4, 1, 6));
    world.setBlockToAir(pos.add(4, 1, 5));
    world.setBlockToAir(pos.add(4, 1, 4));
    world.setBlockToAir(pos.add(4, 1, 3));
    world.setBlockState(pos.add(4, 1, 2), Blocks.bookshelf.getDefaultState());
    world.setBlockState(pos.add(4, 1, 1), Blocks.planks.getDefaultState());
    world.setBlockState(pos.add(5, 1, 9), Blocks.planks.getDefaultState());
    world.setBlockToAir(pos.add(5, 1, 8));
    world.setBlockToAir(pos.add(5, 1, 7));
    world.setBlockToAir(pos.add(5, 1, 6));
    world.setBlockToAir(pos.add(5, 1, 5));
    world.setBlockToAir(pos.add(5, 1, 4));
    world.setBlockToAir(pos.add(5, 1, 3));
    world.setBlockState(pos.add(5, 1, 2), Blocks.bookshelf.getDefaultState());
    world.setBlockState(pos.add(5, 1, 1), Blocks.planks.getDefaultState());
    world.setBlockState(pos.add(6, 1, 9), Blocks.planks.getDefaultState());
    world.setBlockToAir(pos.add(6, 1, 8));
    world.setBlockState(pos.add(6, 1, 7), Blocks.birch_fence.getDefaultState());
    world.setBlockToAir(pos.add(6, 1, 6));
    world.setBlockToAir(pos.add(6, 1, 5));
    world.setBlockToAir(pos.add(6, 1, 4));
    world.setBlockToAir(pos.add(6, 1, 3));
    world.setBlockState(pos.add(6, 1, 2), Blocks.bookshelf.getDefaultState());
    world.setBlockState(pos.add(6, 1, 1), Blocks.planks.getDefaultState());
    world.setBlockState(pos.add(7, 1, 9), Blocks.planks.getDefaultState());
    world.setBlockToAir(pos.add(7, 1, 8));
    world.setBlockToAir(pos.add(7, 1, 7));
    world.setBlockToAir(pos.add(7, 1, 6));
    world.setBlockToAir(pos.add(7, 1, 5));
    world.setBlockToAir(pos.add(7, 1, 4));
    world.setBlockToAir(pos.add(7, 1, 3));
    world.setBlockState(pos.add(7, 1, 2), Blocks.bookshelf.getDefaultState());
    world.setBlockState(pos.add(7, 1, 1), Blocks.planks.getDefaultState());
    world.setBlockState(pos.add(8, 1, 9), Blocks.planks.getDefaultState());
    world.setBlockState(pos.add(8, 1, 8), Blocks.bookshelf.getDefaultState());
    world.setBlockState(pos.add(8, 1, 7), Blocks.furnace.getDefaultState());
    world.setBlockState(pos.add(8, 1, 6), Blocks.furnace.getDefaultState());

    generateChest(world, pos.add(8, 1, 5), 5);

    world.setBlockState(pos.add(8, 1, 4), Blocks.crafting_table.getDefaultState());
    world.setBlockToAir(pos.add(8, 1, 3));
    world.setBlockState(pos.add(8, 1, 2), Blocks.bookshelf.getDefaultState());
    world.setBlockState(pos.add(8, 1, 1), Blocks.planks.getDefaultState());
    world.setBlockState(pos.add(9, 1, 9), Blocks.log.getDefaultState());
    world.setBlockState(pos.add(9, 1, 8), Blocks.planks.getDefaultState());
    world.setBlockState(pos.add(9, 1, 7), Blocks.planks.getDefaultState());
    world.setBlockState(pos.add(9, 1, 6), Blocks.planks.getDefaultState());
    world.setBlockState(pos.add(9, 1, 5), Blocks.planks.getDefaultState());
    world.setBlockState(pos.add(9, 1, 4), Blocks.planks.getDefaultState());
    world.setBlockState(pos.add(9, 1, 3), Blocks.planks.getDefaultState());
    world.setBlockState(pos.add(9, 1, 2), Blocks.planks.getDefaultState());
    world.setBlockState(pos.add(9, 1, 1), Blocks.log.getDefaultState());
    world.setBlockState(pos.add(1, 2, 9), Blocks.log.getDefaultState());
    world.setBlockState(pos.add(1, 2, 8), Blocks.glass_pane.getDefaultState());
    world.setBlockState(pos.add(1, 2, 7), Blocks.glass_pane.getDefaultState());
    world.setBlockState(pos.add(1, 2, 6), Blocks.planks.getDefaultState());
    world.setBlockState(pos.add(1, 2, 4), Blocks.planks.getDefaultState());
    world.setBlockState(pos.add(1, 2, 3), Blocks.glass_pane.getDefaultState());
    world.setBlockState(pos.add(1, 2, 2), Blocks.glass_pane.getDefaultState());
    world.setBlockState(pos.add(1, 2, 1), Blocks.log.getDefaultState());
    world.setBlockState(pos.add(2, 2, 9), Blocks.planks.getDefaultState());
    world.setBlockToAir(pos.add(2, 2, 8));
    world.setBlockToAir(pos.add(2, 2, 7));
    world.setBlockToAir(pos.add(2, 2, 6));
    world.setBlockToAir(pos.add(2, 2, 5));
    world.setBlockToAir(pos.add(2, 2, 4));
    world.setBlockToAir(pos.add(2, 2, 3));
    world.setBlockState(pos.add(2, 2, 2), Blocks.bookshelf.getDefaultState());
    world.setBlockState(pos.add(2, 2, 1), Blocks.planks.getDefaultState());
    world.setBlockState(pos.add(3, 2, 9), Blocks.glass_pane.getDefaultState());
    world.setBlockToAir(pos.add(3, 2, 8));
    world.setBlockState(pos.add(3, 2, 7), Blocks.wooden_pressure_plate.getDefaultState());
    world.setBlockToAir(pos.add(3, 2, 6));
    world.setBlockToAir(pos.add(3, 2, 5));
    world.setBlockToAir(pos.add(3, 2, 4));
    world.setBlockToAir(pos.add(3, 2, 3));
    world.setBlockToAir(pos.add(3, 2, 2));
    world.setBlockState(pos.add(3, 2, 1), Blocks.glass_pane.getDefaultState());
    world.setBlockState(pos.add(4, 2, 9), Blocks.glass_pane.getDefaultState());
    world.setBlockToAir(pos.add(4, 2, 8));
    world.setBlockToAir(pos.add(4, 2, 7));
    world.setBlockToAir(pos.add(4, 2, 6));
    world.setBlockToAir(pos.add(4, 2, 5));
    world.setBlockToAir(pos.add(4, 2, 4));
    world.setBlockToAir(pos.add(4, 2, 3));
    world.setBlockToAir(pos.add(4, 2, 2));
    world.setBlockState(pos.add(4, 2, 1), Blocks.glass_pane.getDefaultState());
    world.setBlockState(pos.add(5, 2, 10), Blocks.torch.getDefaultState());
    world.setBlockState(pos.add(5, 2, 9), Blocks.planks.getDefaultState());
    world.setBlockState(pos.add(5, 2, 8), Blocks.torch.getDefaultState());
    world.setBlockToAir(pos.add(5, 2, 7));
    world.setBlockToAir(pos.add(5, 2, 6));
    world.setBlockToAir(pos.add(5, 2, 5));
    world.setBlockToAir(pos.add(5, 2, 4));
    world.setBlockToAir(pos.add(5, 2, 3));
    world.setBlockState(pos.add(5, 2, 2), Blocks.torch.getDefaultState());
    world.setBlockState(pos.add(5, 2, 1), Blocks.planks.getDefaultState());
    world.setBlockState(pos.add(5, 2, 0), Blocks.torch.getDefaultState());
    world.setBlockState(pos.add(6, 2, 9), Blocks.glass_pane.getDefaultState());
    world.setBlockToAir(pos.add(6, 2, 8));
    world.setBlockState(pos.add(6, 2, 7), Blocks.wooden_pressure_plate.getDefaultState());
    world.setBlockToAir(pos.add(6, 2, 6));
    world.setBlockToAir(pos.add(6, 2, 5));
    world.setBlockToAir(pos.add(6, 2, 4));
    world.setBlockToAir(pos.add(6, 2, 3));
    world.setBlockToAir(pos.add(6, 2, 2));
    world.setBlockState(pos.add(6, 2, 1), Blocks.glass_pane.getDefaultState());
    world.setBlockState(pos.add(7, 2, 9), Blocks.glass_pane.getDefaultState());
    world.setBlockToAir(pos.add(7, 2, 8));
    world.setBlockToAir(pos.add(7, 2, 7));
    world.setBlockToAir(pos.add(7, 2, 6));
    world.setBlockToAir(pos.add(7, 2, 5));
    world.setBlockToAir(pos.add(7, 2, 4));
    world.setBlockToAir(pos.add(7, 2, 3));
    world.setBlockToAir(pos.add(7, 2, 2));
    world.setBlockState(pos.add(7, 2, 1), Blocks.glass_pane.getDefaultState());
    world.setBlockState(pos.add(8, 2, 9), Blocks.planks.getDefaultState());
    world.setBlockState(pos.add(8, 2, 8), Blocks.bookshelf.getDefaultState());
    world.setBlockToAir(pos.add(8, 2, 7));
    world.setBlockToAir(pos.add(8, 2, 6));
    world.setBlockToAir(pos.add(8, 2, 5));
    world.setBlockToAir(pos.add(8, 2, 4));
    world.setBlockToAir(pos.add(8, 2, 3));
    world.setBlockState(pos.add(8, 2, 2), Blocks.bookshelf.getDefaultState());
    world.setBlockState(pos.add(8, 2, 1), Blocks.planks.getDefaultState());
    world.setBlockState(pos.add(9, 2, 9), Blocks.log.getDefaultState());
    world.setBlockState(pos.add(9, 2, 8), Blocks.planks.getDefaultState());
    world.setBlockState(pos.add(9, 2, 7), Blocks.glass_pane.getDefaultState());
    world.setBlockState(pos.add(9, 2, 6), Blocks.glass_pane.getDefaultState());
    world.setBlockState(pos.add(9, 2, 5), Blocks.planks.getDefaultState());
    world.setBlockState(pos.add(9, 2, 4), Blocks.glass_pane.getDefaultState());
    world.setBlockState(pos.add(9, 2, 3), Blocks.glass_pane.getDefaultState());
    world.setBlockState(pos.add(9, 2, 2), Blocks.planks.getDefaultState());
    world.setBlockState(pos.add(9, 2, 1), Blocks.log.getDefaultState());
    world.setBlockState(pos.add(10, 2, 5), Blocks.torch.getDefaultState());
    world.setBlockState(pos.add(0, 3, 5), Blocks.torch.getDefaultState());
    world.setBlockState(pos.add(1, 3, 10), Blocks.cobblestone.getDefaultState());
    world.setBlockState(pos.add(1, 3, 9), Blocks.log.getDefaultState());
    world.setBlockState(pos.add(1, 3, 8), Blocks.planks.getDefaultState());
    world.setBlockState(pos.add(1, 3, 7), Blocks.planks.getDefaultState());
    world.setBlockState(pos.add(1, 3, 6), Blocks.planks.getDefaultState());
    world.setBlockState(pos.add(1, 3, 5), Blocks.planks.getDefaultState());
    world.setBlockState(pos.add(1, 3, 4), Blocks.planks.getDefaultState());
    world.setBlockState(pos.add(1, 3, 3), Blocks.planks.getDefaultState());
    world.setBlockState(pos.add(1, 3, 2), Blocks.planks.getDefaultState());
    world.setBlockState(pos.add(1, 3, 1), Blocks.log.getDefaultState());
    world.setBlockState(pos.add(1, 3, 0), Blocks.cobblestone.getDefaultState());
    world.setBlockState(pos.add(2, 3, 10), Blocks.cobblestone.getDefaultState());
    world.setBlockState(pos.add(2, 3, 9), Blocks.planks.getDefaultState());
    world.setBlockToAir(pos.add(2, 3, 8));
    world.setBlockState(pos.add(2, 3, 7), Blocks.torch.getDefaultState());
    world.setBlockToAir(pos.add(2, 3, 6));
    world.setBlockToAir(pos.add(2, 3, 5));
    world.setBlockState(pos.add(2, 3, 4), Blocks.torch.getDefaultState());
    world.setBlockToAir(pos.add(2, 3, 3));
    world.setBlockState(pos.add(2, 3, 2), Blocks.bookshelf.getDefaultState());
    world.setBlockState(pos.add(2, 3, 1), Blocks.planks.getDefaultState());
    world.setBlockState(pos.add(2, 3, 0), Blocks.cobblestone.getDefaultState());
    world.setBlockState(pos.add(3, 3, 10), Blocks.cobblestone.getDefaultState());
    world.setBlockState(pos.add(3, 3, 9), Blocks.planks.getDefaultState());
    world.setBlockToAir(pos.add(3, 3, 8));
    world.setBlockToAir(pos.add(3, 3, 7));
    world.setBlockToAir(pos.add(3, 3, 6));
    world.setBlockToAir(pos.add(3, 3, 5));
    world.setBlockToAir(pos.add(3, 3, 4));
    world.setBlockToAir(pos.add(3, 3, 3));
    world.setBlockToAir(pos.add(3, 3, 2));
    world.setBlockState(pos.add(3, 3, 1), Blocks.planks.getDefaultState());
    world.setBlockState(pos.add(3, 3, 0), Blocks.cobblestone.getDefaultState());
    world.setBlockState(pos.add(4, 3, 10), Blocks.cobblestone.getDefaultState());
    world.setBlockState(pos.add(4, 3, 9), Blocks.planks.getDefaultState());
    world.setBlockToAir(pos.add(4, 3, 8));
    world.setBlockToAir(pos.add(4, 3, 7));
    world.setBlockToAir(pos.add(4, 3, 6));
    world.setBlockToAir(pos.add(4, 3, 5));
    world.setBlockToAir(pos.add(4, 3, 4));
    world.setBlockToAir(pos.add(4, 3, 3));
    world.setBlockToAir(pos.add(4, 3, 2));
    world.setBlockState(pos.add(4, 3, 1), Blocks.planks.getDefaultState());
    world.setBlockState(pos.add(4, 3, 0), Blocks.cobblestone.getDefaultState());
    world.setBlockState(pos.add(5, 3, 10), Blocks.cobblestone.getDefaultState());
    world.setBlockState(pos.add(5, 3, 9), Blocks.planks.getDefaultState());
    world.setBlockToAir(pos.add(5, 3, 8));
    world.setBlockToAir(pos.add(5, 3, 7));
    world.setBlockToAir(pos.add(5, 3, 6));
    world.setBlockToAir(pos.add(5, 3, 5));
    world.setBlockToAir(pos.add(5, 3, 4));
    world.setBlockToAir(pos.add(5, 3, 3));
    world.setBlockToAir(pos.add(5, 3, 2));
    world.setBlockState(pos.add(5, 3, 1), Blocks.planks.getDefaultState());
    world.setBlockState(pos.add(5, 3, 0), Blocks.cobblestone.getDefaultState());
    world.setBlockState(pos.add(6, 3, 10), Blocks.cobblestone.getDefaultState());
    world.setBlockState(pos.add(6, 3, 9), Blocks.planks.getDefaultState());
    world.setBlockToAir(pos.add(6, 3, 8));
    world.setBlockToAir(pos.add(6, 3, 7));
    world.setBlockToAir(pos.add(6, 3, 6));
    world.setBlockToAir(pos.add(6, 3, 5));
    world.setBlockToAir(pos.add(6, 3, 4));
    world.setBlockToAir(pos.add(6, 3, 3));
    world.setBlockToAir(pos.add(6, 3, 2));
    world.setBlockState(pos.add(6, 3, 1), Blocks.planks.getDefaultState());
    world.setBlockState(pos.add(6, 3, 0), Blocks.cobblestone.getDefaultState());
    world.setBlockState(pos.add(7, 3, 10), Blocks.cobblestone.getDefaultState());
    world.setBlockState(pos.add(7, 3, 9), Blocks.planks.getDefaultState());
    world.setBlockToAir(pos.add(7, 3, 8));
    world.setBlockToAir(pos.add(7, 3, 7));
    world.setBlockToAir(pos.add(7, 3, 6));
    world.setBlockToAir(pos.add(7, 3, 5));
    world.setBlockToAir(pos.add(7, 3, 4));
    world.setBlockToAir(pos.add(7, 3, 3));
    world.setBlockToAir(pos.add(7, 3, 2));
    world.setBlockState(pos.add(7, 3, 1), Blocks.planks.getDefaultState());
    world.setBlockState(pos.add(7, 3, 0), Blocks.cobblestone.getDefaultState());
    world.setBlockState(pos.add(8, 3, 10), Blocks.cobblestone.getDefaultState());
    world.setBlockState(pos.add(8, 3, 9), Blocks.planks.getDefaultState());
    world.setBlockToAir(pos.add(8, 3, 8));
    world.setBlockState(pos.add(8, 3, 7), Blocks.torch.getDefaultState());
    world.setBlockToAir(pos.add(8, 3, 6));
    world.setBlockToAir(pos.add(8, 3, 5));
    world.setBlockState(pos.add(8, 3, 4), Blocks.torch.getDefaultState());
    world.setBlockToAir(pos.add(8, 3, 3));
    world.setBlockState(pos.add(8, 3, 2), Blocks.bookshelf.getDefaultState());
    world.setBlockState(pos.add(8, 3, 1), Blocks.planks.getDefaultState());
    world.setBlockState(pos.add(8, 3, 0), Blocks.cobblestone.getDefaultState());
    world.setBlockState(pos.add(9, 3, 10), Blocks.cobblestone.getDefaultState());
    world.setBlockState(pos.add(9, 3, 9), Blocks.log.getDefaultState());
    world.setBlockState(pos.add(9, 3, 8), Blocks.planks.getDefaultState());
    world.setBlockState(pos.add(9, 3, 7), Blocks.planks.getDefaultState());
    world.setBlockState(pos.add(9, 3, 6), Blocks.planks.getDefaultState());
    world.setBlockState(pos.add(9, 3, 5), Blocks.planks.getDefaultState());
    world.setBlockState(pos.add(9, 3, 4), Blocks.planks.getDefaultState());
    world.setBlockState(pos.add(9, 3, 3), Blocks.planks.getDefaultState());
    world.setBlockState(pos.add(9, 3, 2), Blocks.planks.getDefaultState());
    world.setBlockState(pos.add(9, 3, 1), Blocks.log.getDefaultState());
    world.setBlockState(pos.add(9, 3, 0), Blocks.cobblestone.getDefaultState());
    world.setBlockState(pos.add(1, 4, 9), Blocks.cobblestone.getDefaultState());
    world.setBlockState(pos.add(1, 4, 8), Blocks.log.getDefaultState());
    world.setBlockState(pos.add(1, 4, 7), Blocks.planks.getDefaultState());
    world.setBlockState(pos.add(1, 4, 6), Blocks.glass_pane.getDefaultState());
    world.setBlockState(pos.add(1, 4, 5), Blocks.glass_pane.getDefaultState());
    world.setBlockState(pos.add(1, 4, 4), Blocks.glass_pane.getDefaultState());
    world.setBlockState(pos.add(1, 4, 3), Blocks.planks.getDefaultState());
    world.setBlockState(pos.add(1, 4, 2), Blocks.log.getDefaultState());
    world.setBlockState(pos.add(1, 4, 1), Blocks.cobblestone.getDefaultState());
    world.setBlockState(pos.add(2, 4, 9), Blocks.cobblestone.getDefaultState());
    world.setBlockToAir(pos.add(2, 4, 8));
    world.setBlockToAir(pos.add(2, 4, 7));
    world.setBlockToAir(pos.add(2, 4, 6));
    world.setBlockToAir(pos.add(2, 4, 5));
    world.setBlockToAir(pos.add(2, 4, 4));
    world.setBlockToAir(pos.add(2, 4, 3));
    world.setBlockToAir(pos.add(2, 4, 2));
    world.setBlockState(pos.add(2, 4, 1), Blocks.cobblestone.getDefaultState());
    world.setBlockState(pos.add(3, 4, 9), Blocks.cobblestone.getDefaultState());
    world.setBlockToAir(pos.add(3, 4, 8));
    world.setBlockToAir(pos.add(3, 4, 7));
    world.setBlockToAir(pos.add(3, 4, 6));
    world.setBlockToAir(pos.add(3, 4, 5));
    world.setBlockToAir(pos.add(3, 4, 4));
    world.setBlockToAir(pos.add(3, 4, 3));
    world.setBlockToAir(pos.add(3, 4, 2));
    world.setBlockState(pos.add(3, 4, 1), Blocks.cobblestone.getDefaultState());
    world.setBlockState(pos.add(4, 4, 9), Blocks.cobblestone.getDefaultState());
    world.setBlockToAir(pos.add(4, 4, 8));
    world.setBlockToAir(pos.add(4, 4, 7));
    world.setBlockToAir(pos.add(4, 4, 6));
    world.setBlockToAir(pos.add(4, 4, 5));
    world.setBlockToAir(pos.add(4, 4, 4));
    world.setBlockToAir(pos.add(4, 4, 3));
    world.setBlockToAir(pos.add(4, 4, 2));
    world.setBlockState(pos.add(4, 4, 1), Blocks.cobblestone.getDefaultState());
    world.setBlockState(pos.add(5, 4, 9), Blocks.cobblestone.getDefaultState());
    world.setBlockToAir(pos.add(5, 4, 8));
    world.setBlockToAir(pos.add(5, 4, 7));
    world.setBlockToAir(pos.add(5, 4, 6));
    world.setBlockToAir(pos.add(5, 4, 5));
    world.setBlockToAir(pos.add(5, 4, 4));
    world.setBlockToAir(pos.add(5, 4, 3));
    world.setBlockToAir(pos.add(5, 4, 2));
    world.setBlockState(pos.add(5, 4, 1), Blocks.cobblestone.getDefaultState());
    world.setBlockState(pos.add(6, 4, 9), Blocks.cobblestone.getDefaultState());
    world.setBlockToAir(pos.add(6, 4, 8));
    world.setBlockToAir(pos.add(6, 4, 7));
    world.setBlockToAir(pos.add(6, 4, 6));
    world.setBlockToAir(pos.add(6, 4, 5));
    world.setBlockToAir(pos.add(6, 4, 4));
    world.setBlockToAir(pos.add(6, 4, 3));
    world.setBlockToAir(pos.add(6, 4, 2));
    world.setBlockState(pos.add(6, 4, 1), Blocks.cobblestone.getDefaultState());
    world.setBlockState(pos.add(7, 4, 9), Blocks.cobblestone.getDefaultState());
    world.setBlockToAir(pos.add(7, 4, 8));
    world.setBlockToAir(pos.add(7, 4, 7));
    world.setBlockToAir(pos.add(7, 4, 6));
    world.setBlockToAir(pos.add(7, 4, 5));
    world.setBlockToAir(pos.add(7, 4, 4));
    world.setBlockToAir(pos.add(7, 4, 3));
    world.setBlockToAir(pos.add(7, 4, 2));
    world.setBlockState(pos.add(7, 4, 1), Blocks.cobblestone.getDefaultState());
    world.setBlockState(pos.add(8, 4, 9), Blocks.cobblestone.getDefaultState());
    world.setBlockToAir(pos.add(8, 4, 8));
    world.setBlockToAir(pos.add(8, 4, 7));
    world.setBlockToAir(pos.add(8, 4, 6));
    world.setBlockToAir(pos.add(8, 4, 5));
    world.setBlockToAir(pos.add(8, 4, 4));
    world.setBlockToAir(pos.add(8, 4, 3));
    world.setBlockToAir(pos.add(8, 4, 2));
    world.setBlockState(pos.add(8, 4, 1), Blocks.cobblestone.getDefaultState());
    world.setBlockState(pos.add(9, 4, 9), Blocks.cobblestone.getDefaultState());
    world.setBlockState(pos.add(9, 4, 8), Blocks.log.getDefaultState());
    world.setBlockState(pos.add(9, 4, 7), Blocks.planks.getDefaultState());
    world.setBlockState(pos.add(9, 4, 6), Blocks.glass_pane.getDefaultState());
    world.setBlockState(pos.add(9, 4, 5), Blocks.glass_pane.getDefaultState());
    world.setBlockState(pos.add(9, 4, 4), Blocks.glass_pane.getDefaultState());
    world.setBlockState(pos.add(9, 4, 3), Blocks.planks.getDefaultState());
    world.setBlockState(pos.add(9, 4, 2), Blocks.log.getDefaultState());
    world.setBlockState(pos.add(9, 4, 1), Blocks.cobblestone.getDefaultState());
    world.setBlockState(pos.add(1, 5, 8), Blocks.cobblestone.getDefaultState());
    world.setBlockState(pos.add(1, 5, 7), Blocks.log.getDefaultState());
    world.setBlockState(pos.add(1, 5, 6), Blocks.planks.getDefaultState());
    world.setBlockState(pos.add(1, 5, 5), Blocks.glass_pane.getDefaultState());
    world.setBlockState(pos.add(1, 5, 4), Blocks.planks.getDefaultState());
    world.setBlockState(pos.add(1, 5, 3), Blocks.log.getDefaultState());
    world.setBlockState(pos.add(1, 5, 2), Blocks.cobblestone.getDefaultState());
    world.setBlockState(pos.add(2, 5, 8), Blocks.cobblestone.getDefaultState());
    world.setBlockToAir(pos.add(2, 5, 7));
    world.setBlockToAir(pos.add(2, 5, 6));
    world.setBlockToAir(pos.add(2, 5, 5));
    world.setBlockToAir(pos.add(2, 5, 4));
    world.setBlockToAir(pos.add(2, 5, 3));
    world.setBlockState(pos.add(2, 5, 2), Blocks.cobblestone.getDefaultState());
    world.setBlockState(pos.add(3, 5, 8), Blocks.cobblestone.getDefaultState());
    world.setBlockToAir(pos.add(3, 5, 7));
    world.setBlockToAir(pos.add(3, 5, 6));
    world.setBlockToAir(pos.add(3, 5, 5));
    world.setBlockToAir(pos.add(3, 5, 4));
    world.setBlockToAir(pos.add(3, 5, 3));
    world.setBlockState(pos.add(3, 5, 2), Blocks.cobblestone.getDefaultState());
    world.setBlockState(pos.add(4, 5, 8), Blocks.cobblestone.getDefaultState());
    world.setBlockToAir(pos.add(4, 5, 7));
    world.setBlockToAir(pos.add(4, 5, 6));
    world.setBlockToAir(pos.add(4, 5, 5));
    world.setBlockToAir(pos.add(4, 5, 4));
    world.setBlockToAir(pos.add(4, 5, 3));
    world.setBlockState(pos.add(4, 5, 2), Blocks.cobblestone.getDefaultState());
    world.setBlockState(pos.add(5, 5, 8), Blocks.cobblestone.getDefaultState());
    world.setBlockToAir(pos.add(5, 5, 7));
    world.setBlockToAir(pos.add(5, 5, 6));
    world.setBlockToAir(pos.add(5, 5, 5));
    world.setBlockToAir(pos.add(5, 5, 4));
    world.setBlockToAir(pos.add(5, 5, 3));
    world.setBlockState(pos.add(5, 5, 2), Blocks.cobblestone.getDefaultState());
    world.setBlockState(pos.add(6, 5, 8), Blocks.cobblestone.getDefaultState());
    world.setBlockToAir(pos.add(6, 5, 7));
    world.setBlockToAir(pos.add(6, 5, 6));
    world.setBlockToAir(pos.add(6, 5, 5));
    world.setBlockToAir(pos.add(6, 5, 4));
    world.setBlockToAir(pos.add(6, 5, 3));
    world.setBlockState(pos.add(6, 5, 2), Blocks.cobblestone.getDefaultState());
    world.setBlockState(pos.add(7, 5, 8), Blocks.cobblestone.getDefaultState());
    world.setBlockToAir(pos.add(7, 5, 7));
    world.setBlockToAir(pos.add(7, 5, 6));
    world.setBlockToAir(pos.add(7, 5, 5));
    world.setBlockToAir(pos.add(7, 5, 4));
    world.setBlockToAir(pos.add(7, 5, 3));
    world.setBlockState(pos.add(7, 5, 2), Blocks.cobblestone.getDefaultState());
    world.setBlockState(pos.add(8, 5, 8), Blocks.cobblestone.getDefaultState());
    world.setBlockToAir(pos.add(8, 5, 7));
    world.setBlockToAir(pos.add(8, 5, 6));
    world.setBlockToAir(pos.add(8, 5, 5));
    world.setBlockToAir(pos.add(8, 5, 4));
    world.setBlockToAir(pos.add(8, 5, 3));
    world.setBlockState(pos.add(8, 5, 2), Blocks.cobblestone.getDefaultState());
    world.setBlockState(pos.add(9, 5, 8), Blocks.cobblestone.getDefaultState());
    world.setBlockState(pos.add(9, 5, 7), Blocks.log.getDefaultState());
    world.setBlockState(pos.add(9, 5, 6), Blocks.planks.getDefaultState());
    world.setBlockState(pos.add(9, 5, 5), Blocks.glass_pane.getDefaultState());
    world.setBlockState(pos.add(9, 5, 4), Blocks.planks.getDefaultState());
    world.setBlockState(pos.add(9, 5, 3), Blocks.log.getDefaultState());
    world.setBlockState(pos.add(9, 5, 2), Blocks.cobblestone.getDefaultState());
    world.setBlockState(pos.add(1, 6, 7), Blocks.cobblestone.getDefaultState());
    world.setBlockState(pos.add(1, 6, 6), Blocks.log.getDefaultState());
    world.setBlockState(pos.add(1, 6, 5), Blocks.planks.getDefaultState());
    world.setBlockState(pos.add(1, 6, 4), Blocks.log.getDefaultState());
    world.setBlockState(pos.add(1, 6, 3), Blocks.cobblestone.getDefaultState());
    world.setBlockState(pos.add(2, 6, 7), Blocks.cobblestone.getDefaultState());
    world.setBlockToAir(pos.add(2, 6, 6));
    world.setBlockToAir(pos.add(2, 6, 5));
    world.setBlockToAir(pos.add(2, 6, 4));
    world.setBlockState(pos.add(2, 6, 3), Blocks.cobblestone.getDefaultState());
    world.setBlockState(pos.add(3, 6, 7), Blocks.cobblestone.getDefaultState());
    world.setBlockToAir(pos.add(3, 6, 6));
    world.setBlockToAir(pos.add(3, 6, 5));
    world.setBlockToAir(pos.add(3, 6, 4));
    world.setBlockState(pos.add(3, 6, 3), Blocks.cobblestone.getDefaultState());
    world.setBlockState(pos.add(4, 6, 7), Blocks.cobblestone.getDefaultState());
    world.setBlockToAir(pos.add(4, 6, 6));
    world.setBlockToAir(pos.add(4, 6, 5));
    world.setBlockToAir(pos.add(4, 6, 4));
    world.setBlockState(pos.add(4, 6, 3), Blocks.cobblestone.getDefaultState());
    world.setBlockState(pos.add(5, 6, 7), Blocks.cobblestone.getDefaultState());
    world.setBlockToAir(pos.add(5, 6, 6));
    world.setBlockToAir(pos.add(5, 6, 5));
    world.setBlockToAir(pos.add(5, 6, 4));
    world.setBlockState(pos.add(5, 6, 3), Blocks.cobblestone.getDefaultState());
    world.setBlockState(pos.add(6, 6, 7), Blocks.cobblestone.getDefaultState());
    world.setBlockToAir(pos.add(6, 6, 6));
    world.setBlockToAir(pos.add(6, 6, 5));
    world.setBlockToAir(pos.add(6, 6, 4));
    world.setBlockState(pos.add(6, 6, 3), Blocks.cobblestone.getDefaultState());
    world.setBlockState(pos.add(7, 6, 7), Blocks.cobblestone.getDefaultState());
    world.setBlockToAir(pos.add(7, 6, 6));
    world.setBlockToAir(pos.add(7, 6, 5));
    world.setBlockToAir(pos.add(7, 6, 4));
    world.setBlockState(pos.add(7, 6, 3), Blocks.cobblestone.getDefaultState());
    world.setBlockState(pos.add(8, 6, 7), Blocks.cobblestone.getDefaultState());
    world.setBlockToAir(pos.add(8, 6, 6));
    world.setBlockToAir(pos.add(8, 6, 5));
    world.setBlockToAir(pos.add(8, 6, 4));
    world.setBlockState(pos.add(8, 6, 3), Blocks.cobblestone.getDefaultState());
    world.setBlockState(pos.add(9, 6, 7), Blocks.cobblestone.getDefaultState());
    world.setBlockState(pos.add(9, 6, 6), Blocks.log.getDefaultState());
    world.setBlockState(pos.add(9, 6, 5), Blocks.planks.getDefaultState());
    world.setBlockState(pos.add(9, 6, 4), Blocks.log.getDefaultState());
    world.setBlockState(pos.add(9, 6, 3), Blocks.cobblestone.getDefaultState());
    world.setBlockState(pos.add(1, 7, 6), Blocks.cobblestone.getDefaultState());
    world.setBlockState(pos.add(1, 7, 5), Blocks.log.getDefaultState());
    world.setBlockState(pos.add(1, 7, 4), Blocks.cobblestone.getDefaultState());
    world.setBlockState(pos.add(2, 7, 6), Blocks.cobblestone.getDefaultState());
    world.setBlockToAir(pos.add(2, 7, 5));
    world.setBlockState(pos.add(2, 7, 4), Blocks.cobblestone.getDefaultState());
    world.setBlockState(pos.add(3, 7, 6), Blocks.cobblestone.getDefaultState());
    world.setBlockToAir(pos.add(3, 7, 5));
    world.setBlockState(pos.add(3, 7, 4), Blocks.cobblestone.getDefaultState());
    world.setBlockState(pos.add(4, 7, 6), Blocks.cobblestone.getDefaultState());
    world.setBlockToAir(pos.add(4, 7, 5));
    world.setBlockState(pos.add(4, 7, 4), Blocks.cobblestone.getDefaultState());
    world.setBlockState(pos.add(5, 7, 6), Blocks.cobblestone.getDefaultState());
    world.setBlockToAir(pos.add(5, 7, 5));
    world.setBlockState(pos.add(5, 7, 4), Blocks.cobblestone.getDefaultState());
    world.setBlockState(pos.add(6, 7, 6), Blocks.cobblestone.getDefaultState());
    world.setBlockToAir(pos.add(6, 7, 5));
    world.setBlockState(pos.add(6, 7, 4), Blocks.cobblestone.getDefaultState());
    world.setBlockState(pos.add(7, 7, 6), Blocks.cobblestone.getDefaultState());
    world.setBlockToAir(pos.add(7, 7, 5));
    world.setBlockState(pos.add(7, 7, 4), Blocks.cobblestone.getDefaultState());
    world.setBlockState(pos.add(8, 7, 6), Blocks.cobblestone.getDefaultState());
    world.setBlockToAir(pos.add(8, 7, 5));
    world.setBlockState(pos.add(8, 7, 4), Blocks.cobblestone.getDefaultState());
    world.setBlockState(pos.add(9, 7, 6), Blocks.cobblestone.getDefaultState());
    world.setBlockState(pos.add(9, 7, 5), Blocks.log.getDefaultState());
    world.setBlockState(pos.add(9, 7, 4), Blocks.cobblestone.getDefaultState());
    world.setBlockState(pos.add(1, 8, 5), Blocks.cobblestone.getDefaultState());
    world.setBlockState(pos.add(2, 8, 5), Blocks.cobblestone.getDefaultState());
    world.setBlockState(pos.add(3, 8, 5), Blocks.cobblestone.getDefaultState());
    world.setBlockState(pos.add(4, 8, 5), Blocks.cobblestone.getDefaultState());
    world.setBlockState(pos.add(5, 8, 5), Blocks.cobblestone.getDefaultState());
    world.setBlockState(pos.add(6, 8, 5), Blocks.cobblestone.getDefaultState());
    world.setBlockState(pos.add(7, 8, 5), Blocks.cobblestone.getDefaultState());
    world.setBlockState(pos.add(8, 8, 5), Blocks.cobblestone.getDefaultState());
    world.setBlockState(pos.add(9, 8, 5), Blocks.cobblestone.getDefaultState());
    return true;
  }
}