package com.github.dayzminecraft.dayzminecraft.common.world.generation.structures;

import com.github.dayzminecraft.dayzminecraft.common.misc.ChatHandler;
import net.minecraft.init.Blocks;
import net.minecraft.item.ItemDoor;
import net.minecraft.util.BlockPos;
import net.minecraft.util.EnumFacing;
import net.minecraft.world.World;

import java.util.Random;

public class StructureFort extends Structure {
  @Override
  public boolean generate(World world, Random rand, BlockPos pos) {
    world.setBlockState(pos.add(1, 0, 5), Blocks.stonebrick.getStateFromMeta(rand.nextInt(3)));
    world.setBlockState(pos.add(1, 0, 4), Blocks.stonebrick.getStateFromMeta(rand.nextInt(3)));
    world.setBlockState(pos.add(1, 0, 3), Blocks.stonebrick.getStateFromMeta(rand.nextInt(3)));
    world.setBlockState(pos.add(1, 0, 2), Blocks.stonebrick.getStateFromMeta(rand.nextInt(3)));
    world.setBlockState(pos.add(1, 0, 1), Blocks.stonebrick.getStateFromMeta(rand.nextInt(3)));
    world.setBlockState(pos.add(2, 0, 5), Blocks.stonebrick.getStateFromMeta(rand.nextInt(3)));
    world.setBlockState(pos.add(2, 0, 4), Blocks.stonebrick.getStateFromMeta(rand.nextInt(3)));
    world.setBlockState(pos.add(2, 0, 3), Blocks.stonebrick.getStateFromMeta(rand.nextInt(3)));
    world.setBlockState(pos.add(2, 0, 2), Blocks.stonebrick.getStateFromMeta(rand.nextInt(3)));
    world.setBlockState(pos.add(2, 0, 1), Blocks.stonebrick.getStateFromMeta(rand.nextInt(3)));
    world.setBlockState(pos.add(3, 0, 5), Blocks.stonebrick.getStateFromMeta(rand.nextInt(3)));
    world.setBlockState(pos.add(3, 0, 4), Blocks.stonebrick.getStateFromMeta(rand.nextInt(3)));
    world.setBlockState(pos.add(3, 0, 3), Blocks.stonebrick.getStateFromMeta(rand.nextInt(3)));
    world.setBlockState(pos.add(3, 0, 2), Blocks.stonebrick.getStateFromMeta(rand.nextInt(3)));
    world.setBlockState(pos.add(3, 0, 1), Blocks.stonebrick.getStateFromMeta(rand.nextInt(3)));
    world.setBlockState(pos.add(4, 0, 5), Blocks.stonebrick.getStateFromMeta(rand.nextInt(3)));
    world.setBlockState(pos.add(4, 0, 4), Blocks.stonebrick.getStateFromMeta(rand.nextInt(3)));
    world.setBlockState(pos.add(4, 0, 3), Blocks.stonebrick.getStateFromMeta(rand.nextInt(3)));
    world.setBlockState(pos.add(4, 0, 2), Blocks.stonebrick.getStateFromMeta(rand.nextInt(3)));
    world.setBlockState(pos.add(4, 0, 1), Blocks.stonebrick.getStateFromMeta(rand.nextInt(3)));
    world.setBlockState(pos.add(5, 0, 5), Blocks.stonebrick.getStateFromMeta(rand.nextInt(3)));
    world.setBlockState(pos.add(5, 0, 4), Blocks.stonebrick.getStateFromMeta(rand.nextInt(3)));
    world.setBlockState(pos.add(5, 0, 3), Blocks.stonebrick.getStateFromMeta(rand.nextInt(3)));
    world.setBlockState(pos.add(5, 0, 2), Blocks.stonebrick.getStateFromMeta(rand.nextInt(3)));
    world.setBlockState(pos.add(5, 0, 1), Blocks.stonebrick.getStateFromMeta(rand.nextInt(3)));
    world.setBlockState(pos.add(1, 1, 5), Blocks.stonebrick.getStateFromMeta(rand.nextInt(3)));
    world.setBlockState(pos.add(1, 1, 4), Blocks.stonebrick.getStateFromMeta(rand.nextInt(3)));
    world.setBlockState(pos.add(1, 1, 3), Blocks.stonebrick.getStateFromMeta(rand.nextInt(3)));
    world.setBlockState(pos.add(1, 1, 2), Blocks.stonebrick.getStateFromMeta(rand.nextInt(3)));
    world.setBlockState(pos.add(1, 1, 1), Blocks.stonebrick.getStateFromMeta(rand.nextInt(3)));
    world.setBlockState(pos.add(2, 1, 5), Blocks.stonebrick.getStateFromMeta(rand.nextInt(3)));
    world.setBlockState(pos.add(2, 1, 4), Blocks.stonebrick.getStateFromMeta(rand.nextInt(3)));
    world.setBlockState(pos.add(2, 1, 3), Blocks.stonebrick.getStateFromMeta(rand.nextInt(3)));
    world.setBlockState(pos.add(2, 1, 2), Blocks.stonebrick.getStateFromMeta(rand.nextInt(3)));
    world.setBlockState(pos.add(2, 1, 1), Blocks.stonebrick.getStateFromMeta(rand.nextInt(3)));
    world.setBlockState(pos.add(3, 1, 5), Blocks.stonebrick.getStateFromMeta(rand.nextInt(3)));
    world.setBlockState(pos.add(3, 1, 4), Blocks.stonebrick.getStateFromMeta(rand.nextInt(3)));
    world.setBlockToAir(pos.add(3, 1, 3));
    world.setBlockState(pos.add(3, 1, 2), Blocks.stonebrick.getStateFromMeta(rand.nextInt(3)));
    world.setBlockState(pos.add(3, 1, 1), Blocks.stonebrick.getStateFromMeta(rand.nextInt(3)));
    world.setBlockState(pos.add(4, 1, 5), Blocks.stonebrick.getStateFromMeta(rand.nextInt(3)));
    world.setBlockState(pos.add(4, 1, 4), Blocks.stone_slab.getStateFromMeta(5));
    world.setBlockToAir(pos.add(4, 1, 3));
    world.setBlockState(pos.add(4, 1, 2), Blocks.stonebrick.getStateFromMeta(rand.nextInt(3)));
    world.setBlockState(pos.add(4, 1, 1), Blocks.stonebrick.getStateFromMeta(rand.nextInt(3)));
    world.setBlockState(pos.add(5, 1, 5), Blocks.stonebrick.getStateFromMeta(rand.nextInt(3)));
    world.setBlockState(pos.add(5, 1, 4), Blocks.stonebrick.getStateFromMeta(rand.nextInt(3)));
    ItemDoor.placeDoor(world, pos.add(5, 1, 3), EnumFacing.NORTH, Blocks.oak_door);
    world.setBlockState(pos.add(5, 1, 2), Blocks.stonebrick.getStateFromMeta(rand.nextInt(3)));
    world.setBlockState(pos.add(5, 1, 1), Blocks.stonebrick.getStateFromMeta(rand.nextInt(3)));
    world.setBlockState(pos.add(1, 2, 5), Blocks.stonebrick.getStateFromMeta(rand.nextInt(3)));
    world.setBlockState(pos.add(1, 2, 4), Blocks.stonebrick.getStateFromMeta(rand.nextInt(3)));
    world.setBlockState(pos.add(1, 2, 3), Blocks.stonebrick.getStateFromMeta(rand.nextInt(3)));
    world.setBlockState(pos.add(1, 2, 2), Blocks.stonebrick.getStateFromMeta(rand.nextInt(3)));
    world.setBlockState(pos.add(1, 2, 1), Blocks.stonebrick.getStateFromMeta(rand.nextInt(3)));
    world.setBlockState(pos.add(2, 2, 5), Blocks.stonebrick.getStateFromMeta(rand.nextInt(3)));
    world.setBlockState(pos.add(2, 2, 4), Blocks.stone_slab.getStateFromMeta(5));
    world.setBlockState(pos.add(2, 2, 3), Blocks.stonebrick.getStateFromMeta(rand.nextInt(3)));
    world.setBlockState(pos.add(2, 2, 2), Blocks.stonebrick.getStateFromMeta(rand.nextInt(3)));
    world.setBlockState(pos.add(2, 2, 1), Blocks.stonebrick.getStateFromMeta(rand.nextInt(3)));
    world.setBlockState(pos.add(3, 2, 5), Blocks.stonebrick.getStateFromMeta(rand.nextInt(3)));
    world.setBlockToAir(pos.add(3, 2, 4));
    world.setBlockToAir(pos.add(3, 2, 3));
    world.setBlockState(pos.add(3, 2, 2), Blocks.stonebrick.getStateFromMeta(rand.nextInt(3)));
    world.setBlockState(pos.add(3, 2, 1), Blocks.stonebrick.getStateFromMeta(rand.nextInt(3)));
    world.setBlockState(pos.add(4, 2, 5), Blocks.stonebrick.getStateFromMeta(rand.nextInt(3)));
    world.setBlockToAir(pos.add(4, 2, 4));
    world.setBlockToAir(pos.add(4, 2, 3));
    world.setBlockState(pos.add(4, 2, 2), Blocks.stonebrick.getStateFromMeta(rand.nextInt(3)));
    world.setBlockState(pos.add(4, 2, 1), Blocks.stonebrick.getStateFromMeta(rand.nextInt(3)));
    world.setBlockState(pos.add(5, 2, 5), Blocks.stonebrick.getStateFromMeta(rand.nextInt(3)));
    world.setBlockState(pos.add(5, 2, 4), Blocks.stonebrick.getStateFromMeta(rand.nextInt(3)));
    world.setBlockState(pos.add(5, 2, 2), Blocks.stonebrick.getStateFromMeta(rand.nextInt(3)));
    world.setBlockState(pos.add(5, 2, 1), Blocks.stonebrick.getStateFromMeta(rand.nextInt(3)));
    world.setBlockState(pos.add(1, 3, 5), Blocks.stonebrick.getStateFromMeta(rand.nextInt(3)));
    world.setBlockState(pos.add(1, 3, 4), Blocks.stonebrick.getStateFromMeta(rand.nextInt(3)));
    world.setBlockState(pos.add(1, 3, 3), Blocks.stonebrick.getStateFromMeta(rand.nextInt(3)));
    world.setBlockState(pos.add(1, 3, 2), Blocks.stonebrick.getStateFromMeta(rand.nextInt(3)));
    world.setBlockState(pos.add(1, 3, 1), Blocks.stonebrick.getStateFromMeta(rand.nextInt(3)));
    world.setBlockState(pos.add(2, 3, 5), Blocks.stonebrick.getStateFromMeta(rand.nextInt(3)));
    world.setBlockToAir(pos.add(2, 3, 4));
    world.setBlockToAir(pos.add(2, 3, 3));
    world.setBlockState(pos.add(2, 3, 2), Blocks.stone_slab.getStateFromMeta(5));
    world.setBlockState(pos.add(2, 3, 1), Blocks.stonebrick.getStateFromMeta(rand.nextInt(3)));
    world.setBlockState(pos.add(3, 3, 5), Blocks.stonebrick.getStateFromMeta(rand.nextInt(3)));
    world.setBlockToAir(pos.add(3, 3, 4));
    world.setBlockToAir(pos.add(3, 3, 3));
    world.setBlockState(pos.add(3, 3, 2), Blocks.stonebrick.getStateFromMeta(rand.nextInt(3)));
    world.setBlockState(pos.add(3, 3, 1), Blocks.stonebrick.getStateFromMeta(rand.nextInt(3)));
    world.setBlockState(pos.add(4, 3, 5), Blocks.stonebrick.getStateFromMeta(rand.nextInt(3)));
    world.setBlockToAir(pos.add(4, 3, 4));
    world.setBlockToAir(pos.add(4, 3, 3));
    world.setBlockState(pos.add(4, 3, 2), Blocks.stonebrick.getStateFromMeta(rand.nextInt(3)));
    world.setBlockState(pos.add(4, 3, 1), Blocks.stonebrick.getStateFromMeta(rand.nextInt(3)));
    world.setBlockState(pos.add(5, 3, 5), Blocks.stonebrick.getStateFromMeta(rand.nextInt(3)));
    world.setBlockState(pos.add(5, 3, 4), Blocks.stonebrick.getStateFromMeta(rand.nextInt(3)));
    world.setBlockState(pos.add(5, 3, 3), Blocks.stonebrick.getStateFromMeta(rand.nextInt(3)));
    world.setBlockState(pos.add(5, 3, 2), Blocks.stonebrick.getStateFromMeta(rand.nextInt(3)));
    world.setBlockState(pos.add(5, 3, 1), Blocks.stonebrick.getStateFromMeta(rand.nextInt(3)));
    world.setBlockState(pos.add(0, 4, 3), Blocks.torch.getDefaultState());
    world.setBlockState(pos.add(1, 4, 5), Blocks.stonebrick.getStateFromMeta(rand.nextInt(3)));
    world.setBlockState(pos.add(1, 4, 4), Blocks.stonebrick.getStateFromMeta(rand.nextInt(3)));
    world.setBlockState(pos.add(1, 4, 3), Blocks.stonebrick.getStateFromMeta(rand.nextInt(3)));
    world.setBlockState(pos.add(1, 4, 2), Blocks.stonebrick.getStateFromMeta(rand.nextInt(3)));
    world.setBlockState(pos.add(1, 4, 1), Blocks.stonebrick.getStateFromMeta(rand.nextInt(3)));
    world.setBlockState(pos.add(2, 4, 5), Blocks.stonebrick.getStateFromMeta(rand.nextInt(3)));
    world.setBlockToAir(pos.add(2, 4, 4));
    world.setBlockState(pos.add(2, 4, 3), Blocks.torch.getDefaultState());
    world.setBlockToAir(pos.add(2, 4, 2));
    world.setBlockState(pos.add(2, 4, 1), Blocks.stonebrick.getStateFromMeta(rand.nextInt(3)));
    world.setBlockState(pos.add(3, 4, 6), Blocks.torch.getDefaultState());
    world.setBlockState(pos.add(3, 4, 5), Blocks.stonebrick.getStateFromMeta(rand.nextInt(3)));
    world.setBlockToAir(pos.add(3, 4, 4));
    world.setBlockToAir(pos.add(3, 4, 3));
    world.setBlockToAir(pos.add(3, 4, 2));
    world.setBlockState(pos.add(3, 4, 1), Blocks.stonebrick.getStateFromMeta(rand.nextInt(3)));
    world.setBlockState(pos.add(3, 4, 0), Blocks.torch.getDefaultState());
    world.setBlockState(pos.add(4, 4, 5), Blocks.stonebrick.getStateFromMeta(rand.nextInt(3)));
    world.setBlockToAir(pos.add(4, 4, 4));
    world.setBlockState(pos.add(4, 4, 3), Blocks.stonebrick.getStateFromMeta(rand.nextInt(3)));
    world.setBlockState(pos.add(4, 4, 2), Blocks.stone_slab.getStateFromMeta(5));
    world.setBlockState(pos.add(4, 4, 1), Blocks.stonebrick.getStateFromMeta(rand.nextInt(3)));
    world.setBlockState(pos.add(5, 4, 5), Blocks.stonebrick.getStateFromMeta(rand.nextInt(3)));
    world.setBlockState(pos.add(5, 4, 4), Blocks.stonebrick.getStateFromMeta(rand.nextInt(3)));
    world.setBlockState(pos.add(5, 4, 3), Blocks.stonebrick.getStateFromMeta(rand.nextInt(3)));
    world.setBlockState(pos.add(5, 4, 2), Blocks.stonebrick.getStateFromMeta(rand.nextInt(3)));
    world.setBlockState(pos.add(5, 4, 1), Blocks.stonebrick.getStateFromMeta(rand.nextInt(3)));
    world.setBlockState(pos.add(6, 4, 3), Blocks.torch.getDefaultState());
    world.setBlockState(pos.add(1, 5, 5), Blocks.stonebrick.getStateFromMeta(rand.nextInt(3)));
    world.setBlockState(pos.add(1, 5, 4), Blocks.stonebrick.getStateFromMeta(rand.nextInt(3)));
    world.setBlockState(pos.add(1, 5, 3), Blocks.stonebrick.getStateFromMeta(rand.nextInt(3)));
    world.setBlockState(pos.add(1, 5, 2), Blocks.stonebrick.getStateFromMeta(rand.nextInt(3)));
    world.setBlockState(pos.add(1, 5, 1), Blocks.stonebrick.getStateFromMeta(rand.nextInt(3)));
    world.setBlockState(pos.add(2, 5, 5), Blocks.stonebrick.getStateFromMeta(rand.nextInt(3)));
    world.setBlockToAir(pos.add(2, 5, 4));
    world.setBlockToAir(pos.add(2, 5, 3));
    world.setBlockToAir(pos.add(2, 5, 2));
    world.setBlockState(pos.add(2, 5, 1), Blocks.stonebrick.getStateFromMeta(rand.nextInt(3)));
    world.setBlockState(pos.add(3, 5, 5), Blocks.stonebrick.getStateFromMeta(rand.nextInt(3)));
    world.setBlockState(pos.add(3, 5, 4), Blocks.stonebrick.getStateFromMeta(rand.nextInt(3)));
    world.setBlockToAir(pos.add(3, 5, 3));
    world.setBlockToAir(pos.add(3, 5, 2));
    world.setBlockState(pos.add(3, 5, 1), Blocks.stonebrick.getStateFromMeta(rand.nextInt(3)));
    world.setBlockState(pos.add(4, 5, 5), Blocks.stonebrick.getStateFromMeta(rand.nextInt(3)));
    world.setBlockState(pos.add(4, 5, 4), Blocks.stone_slab.getStateFromMeta(5));
    world.setBlockToAir(pos.add(4, 5, 3));
    world.setBlockToAir(pos.add(4, 5, 2));
    world.setBlockState(pos.add(4, 5, 1), Blocks.stonebrick.getStateFromMeta(rand.nextInt(3)));
    world.setBlockState(pos.add(5, 5, 5), Blocks.stonebrick.getStateFromMeta(rand.nextInt(3)));
    world.setBlockState(pos.add(5, 5, 4), Blocks.stonebrick.getStateFromMeta(rand.nextInt(3)));
    world.setBlockState(pos.add(5, 5, 3), Blocks.stonebrick.getStateFromMeta(rand.nextInt(3)));
    world.setBlockState(pos.add(5, 5, 2), Blocks.stonebrick.getStateFromMeta(rand.nextInt(3)));
    world.setBlockState(pos.add(5, 5, 1), Blocks.stonebrick.getStateFromMeta(rand.nextInt(3)));
    world.setBlockState(pos.add(1, 6, 5), Blocks.stonebrick.getStateFromMeta(rand.nextInt(3)));
    world.setBlockState(pos.add(1, 6, 4), Blocks.stonebrick.getStateFromMeta(rand.nextInt(3)));
    world.setBlockState(pos.add(1, 6, 3), Blocks.stonebrick.getStateFromMeta(rand.nextInt(3)));
    world.setBlockState(pos.add(1, 6, 2), Blocks.stonebrick.getStateFromMeta(rand.nextInt(3)));
    world.setBlockState(pos.add(1, 6, 1), Blocks.stonebrick.getStateFromMeta(rand.nextInt(3)));
    world.setBlockState(pos.add(2, 6, 5), Blocks.stonebrick.getStateFromMeta(rand.nextInt(3)));
    world.setBlockState(pos.add(2, 6, 4), Blocks.stone_slab.getStateFromMeta(5));
    world.setBlockState(pos.add(2, 6, 3), Blocks.stonebrick.getStateFromMeta(rand.nextInt(3)));
    world.setBlockToAir(pos.add(2, 6, 2));
    world.setBlockState(pos.add(2, 6, 1), Blocks.stonebrick.getStateFromMeta(rand.nextInt(3)));
    world.setBlockState(pos.add(3, 6, 5), Blocks.stonebrick.getStateFromMeta(rand.nextInt(3)));
    world.setBlockToAir(pos.add(3, 6, 4));
    world.setBlockToAir(pos.add(3, 6, 3));
    world.setBlockToAir(pos.add(3, 6, 2));
    world.setBlockState(pos.add(3, 6, 1), Blocks.stonebrick.getStateFromMeta(rand.nextInt(3)));
    world.setBlockState(pos.add(4, 6, 5), Blocks.stonebrick.getStateFromMeta(rand.nextInt(3)));
    world.setBlockToAir(pos.add(4, 6, 4));
    world.setBlockState(pos.add(4, 6, 3), Blocks.torch.getDefaultState());
    world.setBlockToAir(pos.add(4, 6, 2));
    world.setBlockState(pos.add(4, 6, 1), Blocks.stonebrick.getStateFromMeta(rand.nextInt(3)));
    world.setBlockState(pos.add(5, 6, 5), Blocks.stonebrick.getStateFromMeta(rand.nextInt(3)));
    world.setBlockState(pos.add(5, 6, 4), Blocks.stonebrick.getStateFromMeta(rand.nextInt(3)));
    world.setBlockState(pos.add(5, 6, 3), Blocks.stonebrick.getStateFromMeta(rand.nextInt(3)));
    world.setBlockState(pos.add(5, 6, 2), Blocks.stonebrick.getStateFromMeta(rand.nextInt(3)));
    world.setBlockState(pos.add(5, 6, 1), Blocks.stonebrick.getStateFromMeta(rand.nextInt(3)));
    world.setBlockState(pos.add(1, 7, 5), Blocks.stonebrick.getStateFromMeta(rand.nextInt(3)));
    world.setBlockState(pos.add(1, 7, 4), Blocks.stonebrick.getStateFromMeta(rand.nextInt(3)));
    world.setBlockState(pos.add(1, 7, 3), Blocks.stonebrick.getStateFromMeta(rand.nextInt(3)));
    world.setBlockState(pos.add(1, 7, 2), Blocks.stonebrick.getStateFromMeta(rand.nextInt(3)));
    world.setBlockState(pos.add(1, 7, 1), Blocks.stonebrick.getStateFromMeta(rand.nextInt(3)));
    world.setBlockState(pos.add(2, 7, 5), Blocks.stonebrick.getStateFromMeta(rand.nextInt(3)));
    world.setBlockToAir(pos.add(2, 7, 4));
    world.setBlockToAir(pos.add(2, 7, 3));
    world.setBlockState(pos.add(2, 7, 2), Blocks.stone_slab.getStateFromMeta(5));
    world.setBlockState(pos.add(2, 7, 1), Blocks.stonebrick.getStateFromMeta(rand.nextInt(3)));
    world.setBlockState(pos.add(3, 7, 5), Blocks.stonebrick.getStateFromMeta(rand.nextInt(3)));
    world.setBlockToAir(pos.add(3, 7, 4));
    world.setBlockToAir(pos.add(3, 7, 3));
    world.setBlockState(pos.add(3, 7, 2), Blocks.stonebrick.getStateFromMeta(rand.nextInt(3)));
    world.setBlockState(pos.add(3, 7, 1), Blocks.stonebrick.getStateFromMeta(rand.nextInt(3)));
    world.setBlockState(pos.add(4, 7, 5), Blocks.stonebrick.getStateFromMeta(rand.nextInt(3)));
    world.setBlockToAir(pos.add(4, 7, 4));
    world.setBlockToAir(pos.add(4, 7, 3));
    world.setBlockToAir(pos.add(4, 7, 2));
    world.setBlockState(pos.add(4, 7, 1), Blocks.stonebrick.getStateFromMeta(rand.nextInt(3)));
    world.setBlockState(pos.add(5, 7, 5), Blocks.stonebrick.getStateFromMeta(rand.nextInt(3)));
    world.setBlockState(pos.add(5, 7, 4), Blocks.stonebrick.getStateFromMeta(rand.nextInt(3)));
    world.setBlockState(pos.add(5, 7, 3), Blocks.stonebrick.getStateFromMeta(rand.nextInt(3)));
    world.setBlockState(pos.add(5, 7, 2), Blocks.stonebrick.getStateFromMeta(rand.nextInt(3)));
    world.setBlockState(pos.add(5, 7, 1), Blocks.stonebrick.getStateFromMeta(rand.nextInt(3)));
    world.setBlockState(pos.add(1, 8, 5), Blocks.stonebrick.getStateFromMeta(rand.nextInt(3)));
    world.setBlockState(pos.add(1, 8, 4), Blocks.stonebrick.getStateFromMeta(rand.nextInt(3)));
    world.setBlockState(pos.add(1, 8, 3), Blocks.stonebrick.getStateFromMeta(rand.nextInt(3)));
    world.setBlockState(pos.add(1, 8, 2), Blocks.stonebrick.getStateFromMeta(rand.nextInt(3)));
    world.setBlockState(pos.add(1, 8, 1), Blocks.stonebrick.getStateFromMeta(rand.nextInt(3)));
    world.setBlockState(pos.add(2, 8, 5), Blocks.stonebrick.getStateFromMeta(rand.nextInt(3)));
    world.setBlockToAir(pos.add(2, 8, 4));
    world.setBlockState(pos.add(2, 8, 3), Blocks.torch.getDefaultState());
    world.setBlockToAir(pos.add(2, 8, 2));
    world.setBlockState(pos.add(2, 8, 1), Blocks.stonebrick.getStateFromMeta(rand.nextInt(3)));
    world.setBlockState(pos.add(3, 8, 5), Blocks.stonebrick.getStateFromMeta(rand.nextInt(3)));
    world.setBlockToAir(pos.add(3, 8, 4));
    world.setBlockToAir(pos.add(3, 8, 3));
    world.setBlockToAir(pos.add(3, 8, 2));
    world.setBlockState(pos.add(3, 8, 1), Blocks.stonebrick.getStateFromMeta(rand.nextInt(3)));
    world.setBlockState(pos.add(4, 8, 5), Blocks.stonebrick.getStateFromMeta(rand.nextInt(3)));
    world.setBlockToAir(pos.add(4, 8, 4));
    world.setBlockState(pos.add(4, 8, 3), Blocks.stonebrick.getStateFromMeta(rand.nextInt(3)));
    world.setBlockState(pos.add(4, 8, 2), Blocks.stone_slab.getStateFromMeta(5));
    world.setBlockState(pos.add(4, 8, 1), Blocks.stonebrick.getStateFromMeta(rand.nextInt(3)));
    world.setBlockState(pos.add(5, 8, 5), Blocks.stonebrick.getStateFromMeta(rand.nextInt(3)));
    world.setBlockState(pos.add(5, 8, 4), Blocks.stonebrick.getStateFromMeta(rand.nextInt(3)));
    world.setBlockState(pos.add(5, 8, 3), Blocks.stonebrick.getStateFromMeta(rand.nextInt(3)));
    world.setBlockState(pos.add(5, 8, 2), Blocks.stonebrick.getStateFromMeta(rand.nextInt(3)));
    world.setBlockState(pos.add(5, 8, 1), Blocks.stonebrick.getStateFromMeta(rand.nextInt(3)));
    world.setBlockState(pos.add(1, 9, 5), Blocks.stonebrick.getStateFromMeta(rand.nextInt(3)));
    world.setBlockState(pos.add(1, 9, 4), Blocks.stonebrick.getStateFromMeta(rand.nextInt(3)));
    world.setBlockState(pos.add(1, 9, 3), Blocks.stonebrick.getStateFromMeta(rand.nextInt(3)));
    world.setBlockState(pos.add(1, 9, 2), Blocks.stonebrick.getStateFromMeta(rand.nextInt(3)));
    world.setBlockState(pos.add(1, 9, 1), Blocks.stonebrick.getStateFromMeta(rand.nextInt(3)));
    world.setBlockState(pos.add(2, 9, 5), Blocks.stonebrick.getStateFromMeta(rand.nextInt(3)));
    world.setBlockToAir(pos.add(2, 9, 4));
    world.setBlockToAir(pos.add(2, 9, 3));
    world.setBlockToAir(pos.add(2, 9, 2));
    world.setBlockState(pos.add(2, 9, 1), Blocks.stonebrick.getStateFromMeta(rand.nextInt(3)));
    world.setBlockState(pos.add(3, 9, 5), Blocks.stonebrick.getStateFromMeta(rand.nextInt(3)));
    world.setBlockState(pos.add(3, 9, 4), Blocks.stonebrick.getStateFromMeta(rand.nextInt(3)));
    world.setBlockToAir(pos.add(3, 9, 3));
    world.setBlockToAir(pos.add(3, 9, 2));
    world.setBlockState(pos.add(3, 9, 1), Blocks.stonebrick.getStateFromMeta(rand.nextInt(3)));
    world.setBlockState(pos.add(4, 9, 5), Blocks.stonebrick.getStateFromMeta(rand.nextInt(3)));
    world.setBlockState(pos.add(4, 9, 4), Blocks.stone_slab.getStateFromMeta(5));
    world.setBlockToAir(pos.add(4, 9, 3));
    world.setBlockToAir(pos.add(4, 9, 2));
    world.setBlockState(pos.add(4, 9, 1), Blocks.stonebrick.getStateFromMeta(rand.nextInt(3)));
    world.setBlockState(pos.add(5, 9, 5), Blocks.stonebrick.getStateFromMeta(rand.nextInt(3)));
    world.setBlockState(pos.add(5, 9, 4), Blocks.stonebrick.getStateFromMeta(rand.nextInt(3)));
    world.setBlockState(pos.add(5, 9, 3), Blocks.stonebrick.getStateFromMeta(rand.nextInt(3)));
    world.setBlockState(pos.add(5, 9, 2), Blocks.stonebrick.getStateFromMeta(rand.nextInt(3)));
    world.setBlockState(pos.add(5, 9, 1), Blocks.stonebrick.getStateFromMeta(rand.nextInt(3)));
    world.setBlockState(pos.add(0, 10, 6), Blocks.stonebrick.getStateFromMeta(rand.nextInt(3)));
    world.setBlockState(pos.add(0, 10, 5), Blocks.stonebrick.getStateFromMeta(rand.nextInt(3)));
    world.setBlockState(pos.add(0, 10, 4), Blocks.stonebrick.getStateFromMeta(rand.nextInt(3)));
    world.setBlockState(pos.add(0, 10, 3), Blocks.stonebrick.getStateFromMeta(rand.nextInt(3)));
    world.setBlockState(pos.add(0, 10, 2), Blocks.stonebrick.getStateFromMeta(rand.nextInt(3)));
    world.setBlockState(pos.add(0, 10, 1), Blocks.stonebrick.getStateFromMeta(rand.nextInt(3)));
    world.setBlockState(pos.add(0, 10, 0), Blocks.stonebrick.getStateFromMeta(rand.nextInt(3)));
    world.setBlockState(pos.add(1, 10, 6), Blocks.stonebrick.getStateFromMeta(rand.nextInt(3)));
    world.setBlockState(pos.add(1, 10, 5), Blocks.stonebrick.getStateFromMeta(rand.nextInt(3)));
    world.setBlockState(pos.add(1, 10, 4), Blocks.stonebrick.getStateFromMeta(rand.nextInt(3)));
    world.setBlockState(pos.add(1, 10, 3), Blocks.stonebrick.getStateFromMeta(rand.nextInt(3)));
    world.setBlockState(pos.add(1, 10, 2), Blocks.stonebrick.getStateFromMeta(rand.nextInt(3)));
    world.setBlockState(pos.add(1, 10, 1), Blocks.stonebrick.getStateFromMeta(rand.nextInt(3)));
    world.setBlockState(pos.add(1, 10, 0), Blocks.stonebrick.getStateFromMeta(rand.nextInt(3)));
    world.setBlockState(pos.add(2, 10, 6), Blocks.stonebrick.getStateFromMeta(rand.nextInt(3)));
    world.setBlockState(pos.add(2, 10, 5), Blocks.stonebrick.getStateFromMeta(rand.nextInt(3)));
    world.setBlockState(pos.add(2, 10, 4), Blocks.stone_slab.getStateFromMeta(5));
    world.setBlockState(pos.add(2, 10, 3), Blocks.stonebrick.getStateFromMeta(rand.nextInt(3)));
    world.setBlockState(pos.add(2, 10, 2), Blocks.stonebrick.getStateFromMeta(rand.nextInt(3)));
    world.setBlockState(pos.add(2, 10, 1), Blocks.stonebrick.getStateFromMeta(rand.nextInt(3)));
    world.setBlockState(pos.add(2, 10, 0), Blocks.stonebrick.getStateFromMeta(rand.nextInt(3)));
    world.setBlockState(pos.add(3, 10, 6), Blocks.stonebrick.getStateFromMeta(rand.nextInt(3)));
    world.setBlockState(pos.add(3, 10, 5), Blocks.stonebrick.getStateFromMeta(rand.nextInt(3)));
    world.setBlockToAir(pos.add(3, 10, 4));
    world.setBlockToAir(pos.add(3, 10, 3));
    world.setBlockToAir(pos.add(3, 10, 2));
    world.setBlockState(pos.add(3, 10, 1), Blocks.stonebrick.getStateFromMeta(rand.nextInt(3)));
    world.setBlockState(pos.add(3, 10, 0), Blocks.stonebrick.getStateFromMeta(rand.nextInt(3)));
    world.setBlockState(pos.add(4, 10, 6), Blocks.stonebrick.getStateFromMeta(rand.nextInt(3)));
    world.setBlockState(pos.add(4, 10, 5), Blocks.stonebrick.getStateFromMeta(rand.nextInt(3)));
    world.setBlockToAir(pos.add(4, 10, 4));
    world.setBlockToAir(pos.add(4, 10, 3));
    world.setBlockToAir(pos.add(4, 10, 2));
    world.setBlockState(pos.add(4, 10, 1), Blocks.stonebrick.getStateFromMeta(rand.nextInt(3)));
    world.setBlockState(pos.add(4, 10, 0), Blocks.stonebrick.getStateFromMeta(rand.nextInt(3)));
    world.setBlockState(pos.add(5, 10, 6), Blocks.stonebrick.getStateFromMeta(rand.nextInt(3)));
    world.setBlockState(pos.add(5, 10, 5), Blocks.stonebrick.getStateFromMeta(rand.nextInt(3)));
    world.setBlockState(pos.add(5, 10, 4), Blocks.stonebrick.getStateFromMeta(rand.nextInt(3)));
    world.setBlockState(pos.add(5, 10, 3), Blocks.stonebrick.getStateFromMeta(rand.nextInt(3)));
    world.setBlockState(pos.add(5, 10, 2), Blocks.stonebrick.getStateFromMeta(rand.nextInt(3)));
    world.setBlockState(pos.add(5, 10, 1), Blocks.stonebrick.getStateFromMeta(rand.nextInt(3)));
    world.setBlockState(pos.add(5, 10, 0), Blocks.stonebrick.getStateFromMeta(rand.nextInt(3)));
    world.setBlockState(pos.add(6, 10, 6), Blocks.stonebrick.getStateFromMeta(rand.nextInt(3)));
    world.setBlockState(pos.add(6, 10, 5), Blocks.stonebrick.getStateFromMeta(rand.nextInt(3)));
    world.setBlockState(pos.add(6, 10, 4), Blocks.stonebrick.getStateFromMeta(rand.nextInt(3)));
    world.setBlockState(pos.add(6, 10, 3), Blocks.stonebrick.getStateFromMeta(rand.nextInt(3)));
    world.setBlockState(pos.add(6, 10, 2), Blocks.stonebrick.getStateFromMeta(rand.nextInt(3)));
    world.setBlockState(pos.add(6, 10, 1), Blocks.stonebrick.getStateFromMeta(rand.nextInt(3)));
    world.setBlockState(pos.add(6, 10, 0), Blocks.stonebrick.getStateFromMeta(rand.nextInt(3)));
    world.setBlockState(pos.add(0, 11, 6), Blocks.stonebrick.getStateFromMeta(rand.nextInt(3)));
    world.setBlockState(pos.add(0, 11, 4), Blocks.stonebrick.getStateFromMeta(rand.nextInt(3)));
    world.setBlockState(pos.add(0, 11, 2), Blocks.stonebrick.getStateFromMeta(rand.nextInt(3)));
    world.setBlockState(pos.add(0, 11, 0), Blocks.stonebrick.getStateFromMeta(rand.nextInt(3)));
    world.setBlockToAir(pos.add(1, 11, 5));
    world.setBlockToAir(pos.add(1, 11, 4));
    world.setBlockToAir(pos.add(1, 11, 3));
    world.setBlockToAir(pos.add(1, 11, 2));
    world.setBlockToAir(pos.add(1, 11, 1));
    world.setBlockState(pos.add(2, 11, 6), Blocks.stonebrick.getStateFromMeta(rand.nextInt(3)));
    world.setBlockToAir(pos.add(2, 11, 5));
    world.setBlockToAir(pos.add(2, 11, 4));
    world.setBlockToAir(pos.add(2, 11, 3));
    world.setBlockToAir(pos.add(2, 11, 2));
    world.setBlockToAir(pos.add(2, 11, 1));
    world.setBlockState(pos.add(2, 11, 0), Blocks.stonebrick.getStateFromMeta(rand.nextInt(3)));
    world.setBlockToAir(pos.add(3, 11, 5));
    world.setBlockToAir(pos.add(3, 11, 4));
    world.setBlockToAir(pos.add(3, 11, 3));
    world.setBlockToAir(pos.add(3, 11, 2));
    world.setBlockToAir(pos.add(3, 11, 1));
    world.setBlockState(pos.add(4, 11, 6), Blocks.stonebrick.getStateFromMeta(rand.nextInt(3)));
    world.setBlockToAir(pos.add(4, 11, 5));
    world.setBlockToAir(pos.add(4, 11, 4));
    world.setBlockToAir(pos.add(4, 11, 3));
    world.setBlockToAir(pos.add(4, 11, 2));
    world.setBlockToAir(pos.add(4, 11, 1));
    world.setBlockState(pos.add(4, 11, 0), Blocks.stonebrick.getStateFromMeta(rand.nextInt(3)));
    generateChest(world, pos.add(5, 11, 5), 5);
    world.setBlockToAir(pos.add(5, 11, 4));
    world.setBlockToAir(pos.add(5, 11, 3));
    world.setBlockToAir(pos.add(5, 11, 2));
    world.setBlockToAir(pos.add(5, 11, 1));
    world.setBlockState(pos.add(6, 11, 6), Blocks.stonebrick.getStateFromMeta(rand.nextInt(3)));
    world.setBlockState(pos.add(6, 11, 4), Blocks.stonebrick.getStateFromMeta(rand.nextInt(3)));
    world.setBlockState(pos.add(6, 11, 2), Blocks.stonebrick.getStateFromMeta(rand.nextInt(3)));
    world.setBlockState(pos.add(6, 11, 0), Blocks.stonebrick.getStateFromMeta(rand.nextInt(3)));
    world.setBlockState(pos.add(0, 12, 6), Blocks.torch.getDefaultState());
    world.setBlockState(pos.add(0, 12, 4), Blocks.torch.getDefaultState());
    world.setBlockState(pos.add(0, 12, 2), Blocks.torch.getDefaultState());
    world.setBlockState(pos.add(0, 12, 0), Blocks.torch.getDefaultState());
    world.setBlockState(pos.add(2, 12, 6), Blocks.torch.getDefaultState());
    world.setBlockState(pos.add(2, 12, 0), Blocks.torch.getDefaultState());
    world.setBlockState(pos.add(4, 12, 6), Blocks.torch.getDefaultState());
    world.setBlockState(pos.add(4, 12, 0), Blocks.torch.getDefaultState());
    world.setBlockState(pos.add(6, 12, 6), Blocks.torch.getDefaultState());
    world.setBlockState(pos.add(6, 12, 4), Blocks.torch.getDefaultState());
    world.setBlockState(pos.add(6, 12, 2), Blocks.torch.getDefaultState());
    world.setBlockState(pos.add(6, 12, 0), Blocks.torch.getDefaultState());
    return true;
  }
}